Workbook
Name a: 'Art Sales and Purchases'!$A$3627
Name a: #REF!
Name a: #REF!
Name a: #REF!

Sheet Income
B1: 2022 | C1: 2022 | D1: 2023 | E1: 2023 | F1: 2024 | G1: 2024 | H1: 2025 | I1: 2025
B2: Projected | C2: Actual | D2: Projected | E2: Actual | F2: Projected | G2: Actual | H2: Projected | I2: Actual
A3: Income
A4: Hindman | B4: 92000 | C4: 97876.85 | D4: 110000 | E4: 115000 | F4: 110000 | H4: 110000 | I4: 70618
A5: 216 N. Oak Park Ave | B5: 0 | C5: 125 | D5: 1500 | F5: 1500 | H5: 19500 | I5: 19500
A6: 524 Ferdinand Ave #2 | F6: 20000 | H6: 17000 | I6: 17086.94
A7: GCM Boards | B7: 14000 | C7: 25875 | D7: 14700 | E7: 14700 | F7: 16000 | H7: 21500 | I7: 21500
A8: Art Sales | B8: 10000 | C8: 15000 | D8: 15000 | E8: 54777.25 | F8: 20000 | H8: 20000 | I8: 23055.06
A9: Megan's Income | B9: 67000 | C9: 67000 | D9: 74000 | F9: 0 | H9: 0 | I9: 0
A10: EBITDA | B10: =SUM(B4:B9) | C10: =SUM(C4:C9) | D10: =SUM(D4:D9) | E10: =SUM(E4:E9) | F10: =SUM(F4:F9) | G10: =SUM(G4:G9) | H10: =SUM(H4:H9) | I10: =SUM(I4:I9)
A12: 2025 Actual: I4 Monarch paycheck cash ≠ W-2 Box 1. I5 216 LTR cash $19,500. I6 524 #2 STR platform net LOCKED. I7 GCM 1099-NEC $21,500. I8 Art net $23,055.06 = MATCHED Mercury deals only (Berk lots $30,000 − $22,944.94 Cost) + seals $1,000 + mosaics $15,000. Excludes Sale 6428 $11,000 until Cost. Excludes Aquinas books $1,000 until Cost. David Aaron $13,595 is EPGC Consultant June (not I8). Erdal/Aysel/EOEB/L5 ASK. Not tax advice.
A13: Open the 2025 Data sources tab to see where each 2025 number came from and whether the self-checks MATCH. This file is last year's workbook with 2025 filled. Not tax advice.

Sheet 524 Ferdinand Ave, Unit 2
B1: PROPERTY ADDRESS | C1: 524 Ferdinand Avenue, Unit 2 | P1: 524 Ferdinand Avenue, Unit 2 | AC1: 524 Ferdinand Avenue, Unit 2
B2: INCOME | C2: JAN | D2: FEB | E2: MAR | F2: APR | G2: MAY | H2: JUN | I2: JUL | J2: AUG | K2: SEPT | L2: OCT | M2: NOV | N2: DEC | O2: 2023 YR TOTAL | P2: JAN | Q2: FEB | R2: MAR | S2: APR | T2: MAY | U2: JUN | V2: JUL | W2: AUG | X2: SEPT | Y2: OCT | Z2: NOV | AA2: DEC | AB2: 2024 YR TOTAL | AC2: JAN | AD2: FEB | AE2: MAR | AF2: APR | AG2: MAY | AH2: JUN | AI2: JUL | AJ2: AUG | AK2: SEPT | AL2: OCT | AM2: NOV | AN2: DEC | AO2: 2025 YR TOTAL
B3: MULTI-PROPERTY INCOME OVERVIEW
B4: MULTI-PROPERTY INCOME OVERVIEW | C4: 0 | D4: 0 | E4: 0 | F4: 0 | G4: 0 | H4: 0 | I4: 0 | J4: 0 | K4: 0 | L4: 0 | M4: 0 | N4: 0 | O4: =SUM(C4:N4) | P4: 0 | Q4: 0 | R4: 0 | S4: 0 | T4: 0 | U4: 0 | V4: 0 | W4: 0 | X4: 0 | Y4: 0 | Z4: 0 | AA4: 0 | AB4: =SUM(P4:AA4) | AC4: 0 | AD4: 0 | AE4: 0 | AF4: 0 | AG4: 0 | AH4: 0 | AI4: 0 | AJ4: 0 | AK4: 0 | AL4: 0 | AM4: 0 | AN4: 0 | AO4: =SUM(AC4:AN4)
B5: RENTAL INCOME | M5: 600 | N5: 450 | O5: =SUM(C5:N5) | AA5: 22705 | AB5: =SUM(P5:AA5) | AC5: 0 | AD5: 0 | AE5: 0 | AF5: 0 | AG5: 0 | AH5: 3479.6 | AI5: 3180.81 | AJ5: 1757.5 | AK5: 2690.16 | AL5: 1261.64 | AM5: 1509.84 | AN5: 0 | AO5: =SUM(AC5:AN5)
B6: GROSS RENTAL INCOME | C6: =SUM(C4:C5) | D6: =SUM(D4:D5) | E6: =SUM(E4:E5) | F6: =SUM(F4:F5) | G6: =SUM(G4:G5) | H6: =SUM(H4:H5) | I6: =SUM(I4:I5) | J6: =SUM(J4:J5) | ... N6: =SUM(N4:N5) | O6: =SUM(C6:N6) | P6: =SUM(P4:P5) | Q6: =SUM(Q4:Q5) | R6: =SUM(R4:R5) | S6: =SUM(S4:S5) | T6: =SUM(T4:T5) | U6: =SUM(U4:U5) | V6: =SUM(V4:V5) | W6: =SUM(W4:W5) | ... AA6: =SUM(AA4:AA5) | AB6: =SUM(P6:AA6) | AC6: =SUM(AC4:AC5) | AD6: =SUM(AD4:AD5) | AE6: =SUM(AE4:AE5) | AF6: =SUM(AF4:AF5) | AG6: =SUM(AG4:AG5) | AH6: =SUM(AH4:AH5) | AI6: =SUM(AI4:AI5) | AJ6: =SUM(AJ4:AJ5) | ... AN6: =SUM(AN4:AN5) | AO6: =SUM(AC6:AN6)
B8: EXPENSES | C8: JAN | D8: FEB | E8: MAR | F8: APR | G8: MAY | H8: JUN | I8: JUL | J8: AUG | K8: SEPT | L8: OCT | M8: NOV | N8: DEC | O8: YR TOTAL | P8: JAN | Q8: FEB | R8: MAR | S8: APR | T8: MAY | U8: JUN | V8: JUL | W8: AUG | X8: SEPT | Y8: OCT | Z8: NOV | AA8: DEC | AB8: YR TOTAL | AC8: JAN | AD8: FEB | AE8: MAR | AF8: APR | AG8: MAY | AH8: JUN | AI8: JUL | AJ8: AUG | AK8: SEPT | AL8: OCT | AM8: NOV | AN8: DEC | AO8: YR TOTAL
B10: MULTI-PROPERTY EXPENSES OVERVIEW | C10: 0 | D10: 0 | E10: 0 | F10: 0 | G10: 0 | H10: 0 | I10: 0 | J10: 0 | K10: 0 | L10: 0 | M10: 0 | N10: 0 | O10: =SUM(C10:N10) | P10: 0 | Q10: 0 | R10: 0 | S10: 0 | T10: 0 | U10: 0 | V10: 0 | W10: 0 | X10: 0 | Y10: 0 | Z10: 0 | AA10: 0 | AB10: =SUM(P10:AA10) | AC10: 0 | AD10: 0 | AE10: 0 | AF10: 0 | AG10: 0 | AH10: 0 | AI10: 0 | AJ10: 0 | AK10: 0 | AL10: 0 | AM10: 0 | AN10: 0 | AO10: =SUM(AC10:AN10)
B11: MARKETING / ADVERTISING | C11: 0 | D11: 0 | E11: 0 | F11: 0 | G11: 0 | H11: 0 | I11: 0 | J11: 0 | K11: 0 | L11: 0 | M11: 0 | N11: 0 | O11: =SUM(C11:N11) | P11: 0 | Q11: 0 | R11: 0 | S11: 0 | T11: 0 | U11: 0 | V11: 0 | W11: 0 | X11: 0 | Y11: 0 | Z11: 0 | AA11: 0 | AB11: =SUM(P11:AA11) | AC11: 0 | AD11: 0 | AE11: 0 | AF11: 0 | AG11: 0 | AH11: 0 | AI11: 0 | AJ11: 0 | AK11: 0 | AL11: 0 | AM11: 0 | AN11: 0 | AO11: =SUM(AC11:AN11)
B12: SERVICE FEES | C12: 0 | D12: 0 | E12: 0 | F12: 0 | G12: 0 | H12: 0 | I12: 0 | J12: 0 | K12: 0 | L12: 0 | M12: 0 | N12: 0 | O12: =SUM(C12:N12) | P12: 0 | Q12: 0 | R12: 0 | S12: 0 | T12: 0 | U12: 0 | V12: 0 | W12: 0 | X12: 0 | Y12: 0 | Z12: 0 | AA12: 950.6 | AB12: =SUM(P12:AA12) | AC12: 0 | AD12: 0 | AE12: 0 | AF12: 0 | AG12: 0 | AH12: 0 | AI12: 0 | AJ12: 0 | AK12: 0 | AL12: 0 | AM12: 0 | AN12: 0 | AO12: =SUM(AC12:AN12)
B13: REMITTED TAX | C13: 0 | D13: 0 | E13: 0 | F13: 0 | G13: 0 | H13: 0 | I13: 0 | J13: 0 | K13: 0 | L13: 0 | M13: 0 | N13: 0 | O13: =SUM(C13:N13) | P13: 0 | Q13: 0 | R13: 0 | S13: 0 | T13: 0 | U13: 0 | V13: 0 | W13: 0 | X13: 0 | Y13: 0 | Z13: 0 | AA13: 0 | AB13: =SUM(P13:AA13) | AC13: 0 | AD13: 0 | AE13: 0 | AF13: 0 | AG13: 0 | AH13: 0 | AI13: 0 | AJ13: 0 | AK13: 0 | AL13: 0 | AM13: 0 | AN13: 0 | AO13: =SUM(AC13:AN13)
B14: INSURANCE | O14: =SUM(C14:N14) | AA14: 1455.09 | AB14: =SUM(P14:AA14) | AC14: 0 | AD14: 78.77 | AE14: 78.76 | AF14: 78.76 | AG14: 78.76 | AH14: 78.76 | AI14: 78.76 | AJ14: 80.19 | AK14: 0 | AL14: 0 | AM14: 0 | AN14: 0 | AO14: =SUM(AC14:AN14)
B15: INTERIOR MAINTENANCE | C15: 0 | D15: 0 | E15: 0 | F15: 0 | G15: 0 | H15: 0 | I15: 0 | J15: 0 | K15: 0 | L15: 0 | M15: 0 | N15: 0 | O15: =SUM(C15:N15) | P15: 0 | Q15: 0 | R15: 0 | S15: 0 | T15: 0 | U15: 0 | V15: 0 | W15: 0 | X15: 0 | Y15: 0 | Z15: 0 | AA15: 0 | AB15: =SUM(P15:AA15) | AC15: 7.46 | AD15: 0 | AE15: 52.78 | AF15: 131.4 | AG15: 0 | AH15: 0 | AI15: 0 | AJ15: 0 | AK15: 0 | AL15: 45.6 | AM15: 12.63 | AN15: 0 | AO15: =SUM(AC15:AN15)
B16: EXTERIOR REPAIRS | C16: 0 | D16: 0 | E16: 0 | F16: 0 | G16: 0 | H16: 0 | I16: 0 | J16: 0 | K16: 0 | L16: 0 | M16: 0 | N16: 0 | O16: =SUM(C16:N16) | P16: 0 | Q16: 0 | R16: 0 | S16: 0 | T16: 0 | U16: 0 | V16: 0 | W16: 0 | X16: 0 | Y16: 0 | Z16: 0 | AA16: 0 | AB16: =SUM(P16:AA16) | AC16: 0 | AD16: 66.57 | AE16: 700.77 | AF16: 39.58 | AG16: 0 | AH16: 0 | AI16: 150.06 | AJ16: 16.54 | AK16: 34.87 | AL16: 76.24 | AM16: 32.33 | AN16: 0 | AO16: =SUM(AC16:AN16)
B17: VILLAGE WATER AND REFUSE | C17: 0 | D17: 0 | E17: 0 | F17: 0 | G17: 0 | H17: 0 | I17: 0 | J17: 0 | K17: 0 | L17: 0 | M17: 0 | N17: 0 | O17: =SUM(C17:N17) | P17: 0 | Q17: 0 | R17: 0 | S17: 0 | T17: 0 | U17: 0 | V17: 0 | W17: 0 | X17: 0 | Y17: 0 | Z17: 0 | AA17: 0 | AB17: 1769.42 | AC17: 0 | AD17: 100.56 | AE17: 0 | AF17: 90.68 | AG17: 0 | AH17: 112.84 | AI17: 0 | AJ17: 137.64 | AK17: 0 | AL17: 132.77 | AM17: 0 | AN17: 0 | AO17: 0
B18: GAS | C18: 0 | D18: 0 | E18: 0 | F18: 0 | G18: 0 | H18: 0 | I18: 0 | J18: 26.02 | K18: 110.08 | L18: 137.34 | M18: 31.56 | N18: 62.3 | O18: =SUM(C18:N18) | P18: 62.3 | Q18: 37.13 | R18: 25.46 | S18: 28.11 | T18: 21.2 | U18: 20.5 | V18: 22.27 | W18: 21.6 | X18: 21.6 | Y18: 21.65 | Z18: 24.34 | AA18: 30.76 | AB18: =SUM(P18:AA18) | AC18: 39.7 | AD18: 31.37 | AE18: 32.09 | AF18: 26.31 | AG18: 25.41 | AH18: 24.17 | AI18: 23.53 | AJ18: 22.7 | AK18: 22.71 | AL18: 22.72 | AM18: 0 | AN18: 53.71 | AO18: =SUM(AC18:AN18)
B19: ELECTRIC | C19: 0 | D19: 0 | E19: 0 | F19: 0 | G19: 0 | H19: 0 | I19: 0 | J19: 36.38 | K19: 36.47 | L19: 34.52 | M19: 32.21 | N19: 45.6 | O19: =SUM(C19:N19) | P19: 0 | Q19: 0 | R19: 0 | S19: 0 | T19: 0 | U19: 0 | V19: 0 | AA19: 806.46 | AB19: =SUM(P19:AA19) | AC19: 59.04 | AD19: 57.47 | AE19: 49.15 | AF19: 54.52 | AG19: 49.73 | AH19: 57.54 | AI19: 109 | AJ19: 123.54 | AK19: 106.93 | AL19: 62.88 | AM19: 46.47 | AN19: 52.88 | AO19: =SUM(AC19:AN19)
B20: INTERNET | C20: 0 | D20: 0 | E20: 0 | F20: 0 | G20: 0 | H20: 0 | I20: 0 | J20: 0 | K20: 0 | L20: 0 | M20: 0 | N20: 0 | O20: =SUM(C20:N20) | P20: 50 | Q20: 50 | R20: 50 | S20: 50 | T20: 50 | U20: 50 | V20: 50 | W20: 50 | X20: 50 | Y20: 50 | Z20: 50 | AA20: 50 | AB20: =SUM(P20:AA20) | AC20: 45 | AD20: 45 | AE20: 45 | AF20: 45 | AG20: 50 | AH20: 50 | AI20: 50 | AJ20: 50 | AK20: 50 | AL20: 50 | AM20: 50 | AN20: 0 | AO20: =SUM(AC20:AN20)
B21: CORRESPONDENCE | C21: 0 | D21: 0 | E21: 0 | F21: 0 | G21: 0 | H21: 0 | I21: 0 | J21: 0 | K21: 0 | L21: 0 | M21: 0 | N21: 0 | O21: =SUM(C21:N21) | P21: 0 | Q21: 0 | R21: 0 | S21: 0 | T21: 0 | U21: 0 | V21: 0 | W21: 0 | X21: 0 | Y21: 0 | Z21: 0 | AA21: 0 | AB21: =SUM(P21:AA21) | AC21: 0 | AD21: 0 | AE21: 0 | AF21: 0 | AG21: 0 | AH21: 0 | AI21: 0 | AJ21: 0 | AK21: 0 | AL21: 0 | AM21: 0 | AN21: 0 | AO21: =SUM(AC21:AN21)
B22: INTERIOR DESIGNER/ ORGANIZER FEES | C22: 0 | D22: 0 | E22: 0 | F22: 0 | G22: 0 | H22: 0 | I22: 0 | J22: 0 | K22: 720 | L22: 690 | M22: 240 | N22: 240 | O22: =SUM(C22:N22) | P22: 0 | Q22: 0 | R22: 0 | S22: 0 | T22: 0 | U22: 0 | V22: 0 | W22: 0 | AB22: =SUM(P22:AA22) | AC22: 0 | AD22: 0 | AE22: 0 | AF22: 0 | AG22: 0 | AH22: 0 | AI22: 0 | AJ22: 0 | AO22: =SUM(AC22:AN22)
B23: TRAVEL EXPENSES | C23: 0 | D23: 0 | E23: 0 | F23: 0 | G23: 0 | H23: 0 | I23: 0 | J23: 0 | K23: 0 | L23: 0 | M23: 0 | N23: 0 | O23: =SUM(C23:N23) | P23: 0 | Q23: 0 | R23: 0 | S23: 0 | T23: 0 | U23: 0 | V23: 0 | W23: 0 | X23: 0 | Y23: 0 | Z23: 0 | AA23: 0 | AB23: =SUM(P23:AA23) | AC23: 0 | AD23: 0 | AE23: 0 | AF23: 0 | AG23: 0 | AH23: 0 | AI23: 0 | AJ23: 0 | AK23: 0 | AL23: 0 | AM23: 0 | AN23: 0 | AO23: =SUM(AC23:AN23)
B24: EQUIPMENT/APPLIANCE PURCHASES | C24: 0 | D24: 20 | E24: 0 | F24: 0 | G24: 0 | H24: 0 | I24: 0 | J24: 0 | K24: 0 | L24: 0 | M24: 0 | N24: 220 | O24: =SUM(C24:N24) | P24: 63.42 | Q24: 281.27 | R24: 60.49 | S24: 49.49 | T24: 76.98 | U24: 98 | V24: 0 | W24: 0 | X24: 0 | Y24: 0 | Z24: 0 | AB24: =SUM(P24:AA24) | AC24: 0 | AD24: 0 | AE24: 73.24 | AF24: 0 | AG24: 0 | AH24: 0 | AI24: 0 | AJ24: 0 | AK24: 82.27 | AL24: 0 | AM24: 0 | AN24: 0 | AO24: =SUM(AC24:AN24)
B25: EQUIPMENT/APPLIANCE RENTAL FEES | C25: 0 | D25: 0 | E25: 0 | F25: 0 | G25: 0 | H25: 0 | I25: 0 | J25: 0 | K25: 0 | L25: 0 | M25: 0 | N25: 0 | O25: =SUM(C25:N25) | P25: 0 | Q25: 0 | R25: 0 | S25: 0 | T25: 0 | U25: 0 | V25: 0 | W25: 0 | X25: 0 | Y25: 0 | Z25: 0 | AA25: 0 | AB25: =SUM(P25:AA25) | AC25: 0 | AD25: 0 | AE25: 0 | AF25: 0 | AG25: 0 | AH25: 0 | AI25: 0 | AJ25: 0 | AK25: 0 | AL25: 0 | AM25: 0 | AN25: 0 | AO25: =SUM(AC25:AN25)
B26: LAND TAX | C26: 0 | D26: 0 | E26: 0 | F26: 0 | G26: 0 | H26: 0 | I26: 0 | J26: 0 | K26: 0 | L26: 0 | M26: 0 | N26: 0 | O26: =SUM(C26:N26) | P26: 0 | Q26: 0 | R26: 0 | S26: 0 | T26: 0 | U26: 0 | V26: 0 | W26: 0 | X26: 0 | Y26: 0 | Z26: 0 | AA26: 0 | AB26: =SUM(P26:AA26) | AC26: 0 | AD26: 0 | AE26: 0 | AF26: 0 | AG26: 0 | AH26: 0 | AI26: 0 | AJ26: 0 | AK26: 0 | AL26: 0 | AM26: 0 | AN26: 0 | AO26: =SUM(AC26:AN26)
B27: BORROWING EXPENSES | C27: 0 | D27: 0 | E27: 0 | F27: 0 | G27: 0 | H27: 0 | I27: 0 | J27: 0 | K27: 0 | L27: 0 | M27: 0 | N27: 0 | O27: =SUM(C27:N27) | P27: 0 | Q27: 0 | R27: 0 | S27: 0 | T27: 0 | U27: 0 | V27: 0 | W27: 0 | X27: 0 | Y27: 0 | Z27: 0 | AA27: 0 | AB27: =SUM(P27:AA27) | AC27: 0 | AD27: 0 | AE27: 0 | AF27: 0 | AG27: 0 | AH27: 0 | AI27: 0 | AJ27: 0 | AK27: 0 | AL27: 0 | AM27: 0 | AN27: 0 | AO27: =SUM(AC27:AN27)
B28: LOANS INTEREST | C28: 0 | D28: 0 | E28: 0 | F28: 0 | G28: 0 | H28: 0 | I28: 0 | J28: 0 | K28: 0 | L28: 0 | M28: 0 | N28: 0 | O28: =SUM(C28:N28) | P28: 0 | Q28: 0 | R28: 0 | S28: 0 | T28: 0 | U28: 0 | V28: 0 | W28: 0 | X28: 0 | Y28: 0 | Z28: 0 | AA28: 0 | AB28: =SUM(P28:AA28) | AC28: 0 | AD28: 0 | AE28: 0 | AF28: 0 | AG28: 0 | AH28: 0 | AI28: 0 | AJ28: 0 | AK28: 0 | AL28: 0 | AM28: 0 | AN28: 0 | AO28: =SUM(AC28:AN28)
B29: TRAVEL EXPENSES | C29: 0 | D29: 0 | E29: 0 | F29: 0 | G29: 0 | H29: 0 | I29: 0 | J29: 0 | K29: 0 | L29: 0 | M29: 0 | N29: 0 | O29: =SUM(C29:N29) | P29: 0 | Q29: 0 | R29: 0 | S29: 0 | T29: 0 | U29: 0 | V29: 0 | W29: 0 | X29: 0 | Y29: 0 | Z29: 0 | AA29: 0 | AB29: =SUM(P29:AA29) | AC29: 0 | AD29: 0 | AE29: 0 | AF29: 0 | AG29: 0 | AH29: 0 | AI29: 0 | AJ29: 0 | AK29: 0 | AL29: 0 | AM29: 0 | AN29: 0 | AO29: =SUM(AC29:AN29)
B30: YARD STARTUP CONSTRUCTION | C30: 0 | D30: 0 | E30: 0 | F30: 210.36 | G30: 0 | H30: 0 | I30: 0 | J30: 0 | K30: 0 | L30: 11713.94 | M30: 35.64 | N30: 0 | O30: =SUM(C30:N30) | P30: 0 | Q30: 0 | R30: 0 | T30: 0 | U30: 0 | V30: 0 | W30: 0 | X30: 0 | AA30: 0 | AB30: =SUM(P30:AA30) | AC30: 0 | AD30: 0 | AE30: 0 | AG30: 0 | AH30: 0 | AI30: 0 | AJ30: 0 | AK30: 0 | AN30: 0 | AO30: =SUM(AC30:AN30)
B31: YARD EQUIPMENT | C31: 0 | D31: 0 | E31: 0 | F31: 0 | G31: 0 | H31: 0 | I31: 0 | J31: 0 | K31: 1440.43 | L31: 142.99 | M31: 0 | N31: 0 | O31: =SUM(C31:N31) | P31: 0 | Q31: 0 | R31: 0 | S31: 328.9 | T31: 49.96 | U31: 54.17 | V31: 75.39 | W31: 72.59 | X31: 19.79 | Y31: 89.15 | Z31: 106.99 | AA31: 152.9 | AB31: =SUM(P31:AA31) | AC31: 0 | AD31: 0 | AE31: 0 | AF31: 0 | AG31: 0 | AH31: 0 | AI31: 0 | AJ31: 0 | AK31: 0 | AL31: 0 | AM31: 0 | AN31: 0 | AO31: =SUM(AC31:AN31)
B32: YARD FURNITURE | C32: 0 | D32: 0 | E32: 0 | F32: 0 | G32: 0 | H32: 0 | I32: 0 | J32: 0 | K32: 0 | L32: 2225 | M32: 13 | N32: 215 | O32: =SUM(C32:N32) | P32: 0 | Q32: 0 | R32: 0 | S32: 0 | T32: 0 | U32: 0 | V32: 0 | W32: 0 | X32: 0 | AB32: =SUM(P32:AA32) | AC32: 0 | AD32: 0 | AE32: 0 | AF32: 0 | AG32: 0 | AH32: 0 | AI32: 0 | AJ32: 0 | AK32: 0 | AO32: =SUM(AC32:AN32)
B33: YARD SERVICE | C33: 0 | D33: 0 | E33: 0 | F33: 0 | G33: 0 | H33: 0 | I33: 0 | J33: 0 | K33: 0 | L33: 0 | M33: 0 | N33: 0 | O33: =SUM(C33:N33) | P33: 0 | Q33: 0 | R33: 0 | S33: 318.47 | T33: 0 | U33: 0 | V33: 0 | W33: 236.55 | X33: 0 | Y33: 89.87 | Z33: 0 | AA33: 0 | AB33: =SUM(P33:AA33) | AC33: 0 | AD33: 0 | AE33: 60.95 | AF33: 60.95 | AG33: 445.2 | AH33: 60.95 | AI33: 60.95 | AJ33: 60.95 | AK33: 249 | AL33: 60.95 | AM33: 0 | AN33: 0 | AO33: =SUM(AC33:AN33)
B34: SUPPLIES (Grove Collaborative) | C34: 0 | D34: 0 | E34: 0 | F34: 0 | G34: 0 | H34: 0 | I34: 0 | J34: 0 | K34: 0 | L34: 0 | M34: 0 | N34: 0 | O34: =SUM(C34:N34) | P34: 0 | Q34: 0 | R34: 0 | S34: 0 | T34: 0 | U34: 0 | V34: 0 | W34: 0 | X34: 0 | Y34: 0 | Z34: 0 | AA34: 0 | AB34: =SUM(P34:AA34) | AC34: 110.8 | AD34: 0 | AE34: 92.96 | AF34: 105.25 | AG34: 0 | AH34: 68.73 | AI34: 128.37 | AJ34: 176.17 | AK34: 108.93 | AL34: 0 | AM34: 0 | AN34: 0 | AO34: =SUM(AC34:AN34)
B35: TOTAL EXPENSES | C35: =SUM(C10:C34) | D35: =SUM(D10:D34) | E35: =SUM(E10:E34) | F35: =SUM(F10:F34) | G35: =SUM(G10:G34) | H35: =SUM(H10:H34) | I35: =SUM(I10:I34) | J35: =SUM(J10:J34) | ... N35: =SUM(N10:N34) | O35: =SUM(C35:N35) | P35: =SUM(P10:P34) | Q35: =SUM(Q10:Q34) | R35: =SUM(R10:R34) | S35: =SUM(S10:S34) | T35: =SUM(T10:T34) | U35: =SUM(U10:U34) | V35: =SUM(V10:V34) | W35: =SUM(W10:W34) | ... AA35: =SUM(AA10:AA34) | AB35: =SUM(P35:AA35) | AC35: =SUM(AC10:AC34) | AD35: =SUM(AD10:AD34) | AE35: =SUM(AE10:AE34) | AF35: =SUM(AF10:AF34) | AG35: =SUM(AG10:AG34) | AH35: =SUM(AH10:AH34) | AI35: =SUM(AI10:AI34) | AJ35: =SUM(AJ10:AJ34) | ... AN35: =SUM(AN10:AN34) | AO35: =SUM(AC35:AN35)
B37: YEAR-TO-DATE INCOME LESS EXPENSES | C37: =C6-C35 | D37: =D6-D35 | E37: =E6-E35 | F37: =F6-F35 | G37: =G6-G35 | H37: =H6-H35 | I37: =I6-I35 | J37: =J6-J35 | ... AO37: =AO6-AO35
A39: 2025: platform STR net on RENTAL INCOME (Jun–Nov). TruGreen/Alsip on YARD SERVICE (same as 2024). Grove Collaborative on SUPPLIES (≠ 827 N Grove the house). INSURANCE LOCK 2026-09-20: Travelers was prior 524 home; Geico was the cars. Only State Farm HOME share on this INSURANCE line (50/50 U1/U2). Auto + Geico $540.89 credit personal, not EPGC. Travelers leftover Jan 2025 is 524 home ($0 on cards/Monarch). ELECTRIC yellow — confirm ComEd with Megan. Not tax advice. User 2026-09-20: Travelers + Geico are 524 Ferdinand; Lemonade is 216 Oak Park (not Grove, not 524).

Sheet 216 N. Oak Park Ave
B1: PROPERTY ADDRESS | C1: 216 N. Oak Park Avenue #1Z
B2: INCOME | C2: JAN | D2: FEB | E2: MAR | F2: APR | G2: MAY | H2: JUN | I2: JUL | J2: AUG | K2: SEPT | L2: OCT | M2: NOV | N2: DEC | O2: 2023 YR TOTAL | P2: JAN | Q2: FEB | R2: MAR | S2: APR | T2: MAY | U2: JUN | V2: JUL | W2: AUG | X2: SEPT | Y2: OCT | Z2: NOV | AA2: DEC | AB2: 2024 YR TOTAL | AC2: JAN | AD2: FEB | AE2: MAR | AF2: APR | AG2: MAY | AH2: JUN | AI2: JUL | AJ2: AUG | AK2: SEPT | AL2: OCT | AM2: NOV | AN2: DEC | AO2: 2025 YR TOTAL
B3: MULTI-PROPERTY INCOME OVERVIEW
B4: OTHER INCOME | C4: 0 | D4: 0 | E4: 0 | F4: 0 | G4: 0 | H4: 0 | I4: 0 | J4: 0 | K4: 0 | L4: 0 | M4: 0 | N4: 0 | O4: =SUM(C4:N4) | P4: 0 | Q4: 0 | R4: 0 | S4: 0 | T4: 0 | U4: 0 | V4: 0 | W4: 0 | X4: 0 | Y4: 0 | Z4: 0 | AA4: 0 | AB4: =SUM(P4:AA4) | AC4: 0 | AD4: 0 | AE4: 0 | AF4: 0 | AG4: 0 | AH4: 0 | AI4: 0 | AJ4: 0 | AK4: 0 | AL4: 0 | AM4: 0 | AN4: 0 | AO4: =SUM(AC4:AN4)
B5: RENTAL INCOME | L5: 1775 | M5: 1775 | N5: 1775 | O5: =SUM(C5:N5) | P5: 1775 | Q5: 1775 | R5: 1775 | S5: 1775 | T5: 1775 | U5: 1775 | V5: 1775 | W5: 1775 | X5: 1775 | Y5: 1950 | Z5: 1950 | AA5: 1950 | AB5: =SUM(P5:AA5) | AC5: 1950 | AD5: 1950 | AE5: 1950 | AF5: 1950 | AG5: 1950 | AH5: 1950 | AI5: 1450 | AJ5: 2450 | AK5: 0 | AL5: 0 | AM5: 0 | AN5: 3900 | AO5: =SUM(AC5:AN5)
B6: GROSS RENTAL INCOME | C6: =SUM(C4:C5) | D6: =SUM(D4:D5) | E6: =SUM(E4:E5) | F6: =SUM(F4:F5) | G6: =SUM(G4:G5) | H6: =SUM(H4:H5) | I6: =SUM(I4:I5) | J6: =SUM(J4:J5) | ... N6: =SUM(N4:N5) | O6: =SUM(C6:N6) | P6: =SUM(P4:P5) | Q6: =SUM(Q4:Q5) | R6: =SUM(R4:R5) | S6: =SUM(S4:S5) | T6: =SUM(T4:T5) | U6: =SUM(U4:U5) | V6: =SUM(V4:V5) | W6: =SUM(W4:W5) | ... AA6: =SUM(AA4:AA5) | AB6: =SUM(P6:AA6) | AC6: =SUM(AC4:AC5) | AD6: =SUM(AD4:AD5) | AE6: =SUM(AE4:AE5) | AF6: =SUM(AF4:AF5) | AG6: =SUM(AG4:AG5) | AH6: =SUM(AH4:AH5) | AI6: =SUM(AI4:AI5) | AJ6: =SUM(AJ4:AJ5) | ... AN6: =SUM(AN4:AN5) | AO6: =SUM(AC6:AN6)
B8: EXPENSES | C8: JAN | D8: FEB | E8: MAR | F8: APR | G8: MAY | H8: JUN | I8: JUL | J8: AUG | K8: SEPT | L8: OCT | M8: NOV | N8: DEC | O8: YR TOTAL | P8: JAN | Q8: FEB | R8: MAR | S8: APR | T8: MAY | U8: JUN | V8: JUL | W8: AUG | X8: SEPT | Y8: OCT | Z8: NOV | AA8: DEC | AB8: YR TOTAL | AC8: JAN | AD8: FEB | AE8: MAR | AF8: APR | AG8: MAY | AH8: JUN | AI8: JUL | AJ8: AUG | AK8: SEPT | AL8: OCT | AM8: NOV | AN8: DEC | AO8: YR TOTAL
B9: ='[1]Property Management Overview'!B10
B10: MULTI-PROPERTY EXPENSES OVERVIEW | C10: 0 | D10: 0 | E10: 0 | F10: 0 | G10: 0 | H10: 0 | I10: 0 | J10: 0 | K10: 0 | L10: 0 | M10: 0 | N10: 0 | O10: =SUM(C10:N10) | P10: 0 | Q10: 0 | R10: 0 | S10: 0 | T10: 0 | U10: 0 | V10: 0 | W10: 0 | X10: 0 | Y10: 0 | Z10: 0 | AA10: 0 | AB10: =SUM(P10:AA10) | AC10: 0 | AD10: 0 | AE10: 0 | AF10: 0 | AG10: 0 | AH10: 0 | AI10: 0 | AJ10: 0 | AK10: 0 | AL10: 0 | AM10: 0 | AN10: 0 | AO10: =SUM(AC10:AN10)
B11: MARKETING / ADVERTISING | C11: 0 | D11: 0 | E11: 0 | F11: 0 | G11: 0 | H11: 0 | I11: 0 | J11: 0 | K11: 0 | L11: 0 | M11: 0 | N11: 0 | O11: =SUM(C11:N11) | P11: 0 | Q11: 0 | R11: 0 | S11: 0 | T11: 0 | U11: 0 | V11: 0 | W11: 0 | X11: 0 | Y11: 0 | Z11: 0 | AA11: 0 | AB11: =SUM(P11:AA11) | AC11: 0 | AD11: 0 | AE11: 0 | AF11: 0 | AG11: 0 | AH11: 0 | AI11: 0 | AJ11: 0 | AK11: 0 | AL11: 0 | AM11: 0 | AN11: 0 | AO11: =SUM(AC11:AN11)
B12: SERVICE FEES | C12: 0 | D12: 0 | E12: 0 | F12: 0 | G12: 0 | H12: 0 | I12: 0 | J12: 0 | K12: 0 | L12: 0 | M12: 0 | N12: 0 | O12: =SUM(C12:N12) | P12: 0 | Q12: 0 | R12: 0 | S12: 0 | T12: 0 | U12: 0 | V12: 0 | W12: 0 | X12: 0 | Y12: 0 | Z12: 0 | AA12: 0 | AB12: =SUM(P12:AA12) | AC12: 0 | AD12: 0 | AE12: 0 | AF12: 0 | AG12: 0 | AH12: 0 | AI12: 0 | AJ12: 0 | AK12: 0 | AL12: 0 | AM12: 0 | AN12: 0 | AO12: =SUM(AC12:AN12)
B13: REMITTED TAX | C13: 0 | D13: 0 | E13: 0 | F13: 0 | G13: 0 | H13: 0 | I13: 0 | J13: 0 | K13: 0 | L13: 0 | M13: 0 | N13: 0 | O13: =SUM(C13:N13) | P13: 0 | Q13: 0 | R13: 0 | S13: 0 | T13: 0 | U13: 0 | V13: 0 | W13: 0 | X13: 0 | Y13: 0 | Z13: 0 | AA13: 0 | AB13: =SUM(P13:AA13) | AC13: 0 | AD13: 0 | AE13: 0 | AF13: 0 | AG13: 0 | AH13: 0 | AI13: 0 | AJ13: 0 | AK13: 0 | AL13: 0 | AM13: 0 | AN13: 0 | AO13: =SUM(AC13:AN13)
B14: RENTER'S INSURANCE | C14: 26.75 | D14: 26.75 | E14: 26.75 | F14: 26.75 | G14: 26.75 | H14: 26.75 | I14: 26.75 | J14: 26.75 | K14: 26.75 | L14: 26.75 | M14: 26.75 | N14: 26.75 | O14: =SUM(C14:N14) | P14: 35.08 | Q14: 35.08 | R14: 35.08 | S14: 35.08 | T14: 35.08 | U14: 35.08 | V14: 35.08 | W14: 35.08 | X14: 35.08 | Y14: 35.08 | Z14: 35.08 | AA14: 35.08 | AB14: =SUM(P14:AA14) | AC14: 42.84 | AD14: 42.84 | AE14: 42.84 | AF14: 42.84 | AG14: 42.84 | AH14: 42.84 | AI14: 42.84 | AJ14: 42.84 | AK14: 42.84 | AL14: 42.84 | AM14: 42.84 | AN14: 42.84 | AO14: =SUM(AC14:AN14)
B15: INTERIOR MAINTENANCE | C15: 0 | D15: 0 | E15: 0 | F15: 0 | G15: 0 | H15: 0 | I15: 0 | J15: 0 | K15: 0 | L15: 0 | M15: 0 | N15: 0 | O15: =SUM(C15:N15) | P15: 250 | Q15: 0 | R15: 0 | S15: 0 | U15: 0 | V15: 0 | W15: 0 | X15: 0 | Y15: 0 | Z15: 0 | AA15: 0 | AB15: =SUM(P15:AA15) | AC15: 0 | AD15: 0 | AE15: 0 | AF15: 0 | AG15: 0 | AH15: 0 | AI15: 0 | AJ15: 150 | AK15: 0 | AL15: 0 | AM15: 0 | AN15: 11 | AO15: =SUM(AC15:AN15)
B16: INTERIOR REPAIR | C16: 0 | D16: 0 | E16: 0 | F16: 0 | G16: 0 | H16: 0 | I16: 0 | J16: 0 | K16: 0 | L16: 0 | M16: 0 | N16: 0 | O16: =SUM(C16:N16) | P16: 0 | Q16: 0 | R16: 0 | S16: 0 | T16: 80 | U16: 220 | V16: 0 | W16: 0 | X16: 0 | Y16: 0 | Z16: 250 | AA16: 0 | AB16: =SUM(P16:AA16) | AC16: 0 | AD16: 0 | AE16: 0 | AF16: 0 | AG16: 0 | AH16: 0 | AI16: 0 | AJ16: 0 | AK16: 0 | AL16: 0 | AM16: 0 | AN16: 675 | AO16: =SUM(AC16:AN16)
C17: 0 | D17: 0 | E17: 0 | F17: 0 | G17: 0 | H17: 0 | I17: 0 | J17: 0 | K17: 0 | L17: 0 | M17: 0 | N17: 0 | O17: =SUM(C17:N17) | P17: 0 | Q17: 0 | R17: 0 | S17: 0 | T17: 0 | U17: 0 | V17: 0 | W17: 0 | X17: 0 | Y17: 0 | Z17: 0 | AA17: 0 | AB17: =SUM(P17:AA17) | AC17: 0 | AD17: 0 | AE17: 0 | AF17: 0 | AG17: 0 | AH17: 0 | AI17: 0 | AJ17: 0 | AK17: 0 | AL17: 0 | AM17: 0 | AN17: 0 | AO17: =SUM(AC17:AN17)
C18: 0 | D18: 0 | E18: 0 | F18: 0 | G18: 0 | H18: 0 | I18: 0 | J18: 0 | K18: 0 | L18: 0 | M18: 0 | N18: 0 | O18: =SUM(C18:N18) | P18: 0 | Q18: 0 | R18: 0 | S18: 0 | T18: 0 | U18: 0 | V18: 0 | W18: 0 | X18: 0 | Y18: 0 | Z18: 0 | AA18: 0 | AB18: =SUM(P18:AA18) | AC18: 0 | AD18: 0 | AE18: 0 | AF18: 0 | AG18: 0 | AH18: 0 | AI18: 0 | AJ18: 0 | AK18: 0 | AL18: 0 | AM18: 0 | AN18: 0 | AO18: =SUM(AC18:AN18)
C19: 0 | D19: 0 | E19: 0 | F19: 0 | G19: 0 | H19: 0 | I19: 0 | J19: 0 | K19: 0 | L19: 0 | M19: 0 | N19: 0 | O19: =SUM(C19:N19) | P19: 0 | Q19: 0 | R19: 0 | S19: 0 | T19: 0 | U19: 0 | V19: 0 | W19: 0 | X19: 0 | Y19: 0 | Z19: 0 | AA19: 0 | AB19: =SUM(P19:AA19) | AC19: 0 | AD19: 0 | AE19: 0 | AF19: 0 | AG19: 0 | AH19: 0 | AI19: 0 | AJ19: 0 | AK19: 0 | AL19: 0 | AM19: 0 | AN19: 0 | AO19: =SUM(AC19:AN19)
C20: 0 | D20: 0 | E20: 0 | F20: 0 | G20: 0 | H20: 0 | I20: 0 | J20: 0 | K20: 0 | L20: 0 | M20: 0 | N20: 0 | O20: =SUM(C20:N20) | P20: 0 | Q20: 0 | R20: 0 | S20: 0 | T20: 0 | U20: 0 | V20: 0 | W20: 0 | X20: 0 | Y20: 0 | Z20: 0 | AA20: 0 | AB20: =SUM(P20:AA20) | AC20: 0 | AD20: 0 | AE20: 0 | AF20: 0 | AG20: 0 | AH20: 0 | AI20: 0 | AJ20: 0 | AK20: 0 | AL20: 0 | AM20: 0 | AN20: 0 | AO20: =SUM(AC20:AN20)
C21: 0 | D21: 0 | E21: 0 | F21: 0 | G21: 0 | H21: 0 | I21: 0 | J21: 0 | K21: 0 | L21: 0 | M21: 0 | N21: 0 | O21: =SUM(C21:N21) | P21: 0 | Q21: 0 | R21: 0 | S21: 0 | T21: 0 | U21: 0 | V21: 0 | W21: 0 | X21: 0 | Y21: 0 | Z21: 0 | AA21: 0 | AB21: =SUM(P21:AA21) | AC21: 0 | AD21: 0 | AE21: 0 | AF21: 0 | AG21: 0 | AH21: 0 | AI21: 0 | AJ21: 0 | AK21: 0 | AL21: 0 | AM21: 0 | AN21: 0 | AO21: =SUM(AC21:AN21)
C22: 0 | D22: 0 | E22: 0 | F22: 0 | G22: 0 | H22: 0 | I22: 0 | J22: 0 | K22: 0 | L22: 0 | M22: 0 | N22: 0 | O22: =SUM(C22:N22) | P22: 0 | Q22: 0 | R22: 0 | S22: 0 | T22: 0 | U22: 0 | V22: 0 | W22: 0 | X22: 0 | Y22: 0 | Z22: 0 | AA22: 0 | AB22: =SUM(P22:AA22) | AC22: 0 | AD22: 0 | AE22: 0 | AF22: 0 | AG22: 0 | AH22: 0 | AI22: 0 | AJ22: 0 | AK22: 0 | AL22: 0 | AM22: 0 | AN22: 0 | AO22: =SUM(AC22:AN22)
C23: 0 | D23: 0 | E23: 0 | F23: 0 | G23: 0 | H23: 0 | I23: 0 | J23: 0 | K23: 0 | L23: 0 | M23: 0 | N23: 0 | O23: =SUM(C23:N23) | P23: 0 | Q23: 0 | R23: 0 | S23: 0 | T23: 0 | U23: 0 | V23: 0 | W23: 0 | X23: 0 | Y23: 0 | Z23: 0 | AA23: 0 | AB23: =SUM(P23:AA23) | AC23: 0 | AD23: 0 | AE23: 0 | AF23: 0 | AG23: 0 | AH23: 0 | AI23: 0 | AJ23: 0 | AK23: 0 | AL23: 0 | AM23: 0 | AN23: 0 | AO23: =SUM(AC23:AN23)
C24: 0 | D24: 0 | E24: 0 | F24: 0 | G24: 0 | H24: 0 | I24: 0 | J24: 0 | K24: 0 | L24: 0 | M24: 0 | N24: 0 | O24: =SUM(C24:N24) | P24: 0 | Q24: 0 | R24: 0 | S24: 0 | T24: 0 | U24: 0 | V24: 0 | W24: 0 | X24: 0 | Y24: 0 | Z24: 0 | AA24: 0 | AB24: =SUM(P24:AA24) | AC24: 0 | AD24: 0 | AE24: 0 | AF24: 0 | AG24: 0 | AH24: 0 | AI24: 0 | AJ24: 0 | AK24: 0 | AL24: 0 | AM24: 0 | AN24: 0 | AO24: =SUM(AC24:AN24)
C25: 0 | D25: 0 | E25: 0 | F25: 0 | G25: 0 | H25: 0 | I25: 0 | J25: 0 | K25: 0 | L25: 0 | M25: 0 | N25: 0 | O25: =SUM(C25:N25) | P25: 0 | Q25: 0 | R25: 0 | S25: 0 | T25: 0 | U25: 0 | V25: 0 | W25: 0 | X25: 0 | Y25: 0 | Z25: 0 | AA25: 0 | AB25: =SUM(P25:AA25) | AC25: 0 | AD25: 0 | AE25: 0 | AF25: 0 | AG25: 0 | AH25: 0 | AI25: 0 | AJ25: 0 | AK25: 0 | AL25: 0 | AM25: 0 | AN25: 0 | AO25: =SUM(AC25:AN25)
C26: 0 | D26: 0 | E26: 0 | F26: 0 | G26: 0 | H26: 0 | I26: 0 | J26: 0 | K26: 0 | L26: 13 | M26: 0 | N26: 0 | O26: =SUM(C26:N26) | P26: 0 | Q26: 0 | R26: 0 | S26: 0 | T26: 0 | U26: 0 | V26: 0 | W26: 0 | X26: 0 | Z26: 0 | AA26: 0 | AB26: =SUM(P26:AA26) | AC26: 0 | AD26: 0 | AE26: 0 | AF26: 0 | AG26: 0 | AH26: 0 | AI26: 0 | AJ26: 0 | AK26: 0 | AM26: 0 | AN26: 0 | AO26: =SUM(AC26:AN26)
C27: 0 | D27: 0 | E27: 0 | F27: 0 | G27: 0 | H27: 0 | I27: 0 | J27: 0 | K27: 0 | L27: 0 | M27: 0 | N27: 0 | O27: =SUM(C27:N27) | P27: 0 | Q27: 0 | R27: 0 | S27: 0 | T27: 0 | U27: 0 | V27: 0 | W27: 0 | X27: 0 | Y27: 0 | Z27: 0 | AA27: 0 | AB27: =SUM(P27:AA27) | AC27: 0 | AD27: 0 | AE27: 0 | AF27: 0 | AG27: 0 | AH27: 0 | AI27: 0 | AJ27: 0 | AK27: 0 | AL27: 0 | AM27: 0 | AN27: 0 | AO27: =SUM(AC27:AN27)
C28: 0 | D28: 0 | E28: 0 | F28: 0 | G28: 0 | H28: 0 | I28: 0 | J28: 0 | K28: 0 | L28: 0 | M28: 0 | N28: 0 | O28: =SUM(C28:N28) | P28: 0 | Q28: 0 | R28: 0 | S28: 0 | T28: 0 | U28: 0 | V28: 0 | W28: 0 | X28: 0 | Y28: 0 | Z28: 0 | AA28: 0 | AB28: =SUM(P28:AA28) | AC28: 0 | AD28: 0 | AE28: 0 | AF28: 0 | AG28: 0 | AH28: 0 | AI28: 0 | AJ28: 0 | AK28: 0 | AL28: 0 | AM28: 0 | AN28: 0 | AO28: =SUM(AC28:AN28)
B29: EQUIPMENT/APPLIANCE PURCHASES | C29: 0 | D29: 0 | E29: 0 | F29: 0 | G29: 0 | H29: 0 | I29: 0 | J29: 0 | K29: 0 | L29: 0 | M29: 0 | N29: 0 | O29: =SUM(C29:N29) | P29: 1434.37 | Q29: 0 | R29: 0 | S29: 0 | T29: 0 | U29: 0 | V29: 0 | W29: 0 | X29: 0 | Y29: 0 | Z29: 0 | AA29: 0 | AB29: =SUM(P29:AA29) | AC29: 0 | AD29: 0 | AE29: 0 | AF29: 0 | AG29: 0 | AH29: 0 | AI29: 0 | AJ29: 0 | AK29: 0 | AL29: 0 | AM29: 0 | AN29: 0 | AO29: =SUM(AC29:AN29)
C30: 0 | D30: 0 | E30: 0 | F30: 0 | G30: 0 | H30: 0 | I30: 0 | J30: 0 | K30: 0 | L30: 0 | M30: 0 | N30: 0 | O30: =SUM(C30:N30) | P30: 0 | Q30: 0 | R30: 0 | S30: 0 | T30: 0 | U30: 0 | V30: 0 | W30: 0 | X30: 0 | Y30: 0 | Z30: 0 | AA30: 0 | AB30: =SUM(P30:AA30) | AC30: 0 | AD30: 0 | AE30: 0 | AF30: 0 | AG30: 0 | AH30: 0 | AI30: 0 | AJ30: 0 | AK30: 0 | AL30: 0 | AM30: 0 | AN30: 0 | AO30: =SUM(AC30:AN30)
C31: 0 | D31: 0 | E31: 0 | F31: 0 | G31: 0 | H31: 0 | I31: 0 | J31: 0 | K31: 0 | L31: 0 | M31: 0 | N31: 0 | O31: =SUM(C31:N31) | P31: 0 | Q31: 0 | R31: 0 | S31: 0 | T31: 0 | U31: 0 | V31: 0 | W31: 0 | X31: 0 | Y31: 0 | Z31: 0 | AA31: 0 | AB31: =SUM(P31:AA31) | AC31: 0 | AD31: 0 | AE31: 0 | AF31: 0 | AG31: 0 | AH31: 0 | AI31: 0 | AJ31: 0 | AK31: 0 | AL31: 0 | AM31: 0 | AN31: 0 | AO31: =SUM(AC31:AN31)
C32: 0 | D32: 0 | E32: 0 | F32: 0 | G32: 0 | H32: 0 | I32: 0 | J32: 0 | K32: 0 | L32: 0 | M32: 0 | N32: 0 | O32: =SUM(C32:N32) | P32: 0 | Q32: 0 | R32: 0 | S32: 0 | T32: 0 | U32: 0 | V32: 0 | W32: 0 | X32: 0 | Y32: 0 | Z32: 0 | AA32: 0 | AB32: =SUM(P32:AA32) | AC32: 0 | AD32: 0 | AE32: 0 | AF32: 0 | AG32: 0 | AH32: 0 | AI32: 0 | AJ32: 0 | AK32: 0 | AL32: 0 | AM32: 0 | AN32: 0 | AO32: =SUM(AC32:AN32)
C33: 0 | D33: 0 | E33: 0 | F33: 0 | G33: 0 | H33: 0 | I33: 0 | J33: 0 | K33: 0 | L33: 0 | M33: 0 | N33: 0 | O33: =SUM(C33:N33) | P33: 0 | Q33: 0 | R33: 0 | S33: 0 | T33: 0 | U33: 0 | V33: 0 | W33: 0 | X33: 0 | Y33: 0 | Z33: 0 | AA33: 0 | AB33: =SUM(P33:AA33) | AC33: 0 | AD33: 0 | AE33: 0 | AF33: 0 | AG33: 0 | AH33: 0 | AI33: 0 | AJ33: 0 | AK33: 0 | AL33: 0 | AM33: 0 | AN33: 0 | AO33: =SUM(AC33:AN33)
C34: 0 | D34: 0 | E34: 0 | F34: 0 | G34: 0 | H34: 0 | I34: 0 | J34: 0 | K34: 0 | L34: 0 | M34: 0 | N34: 0 | O34: =SUM(C34:N34) | P34: 0 | Q34: 0 | R34: 0 | S34: 0 | T34: 0 | U34: 0 | V34: 0 | W34: 0 | X34: 0 | Y34: 0 | Z34: 0 | AA34: 0 | AB34: =SUM(P34:AA34) | AC34: 0 | AD34: 0 | AE34: 0 | AF34: 0 | AG34: 0 | AH34: 0 | AI34: 0 | AJ34: 0 | AK34: 0 | AL34: 0 | AM34: 0 | AN34: 0 | AO34: =SUM(AC34:AN34)
B35: MORTGAGE | C35: 1066.27 | D35: 1066.27 | E35: 1066.27 | F35: 1066.27 | G35: 1066.27 | H35: 1066.27 | I35: 1066.27 | J35: 1066.27 | K35: 1066.27 | L35: 1066.27 | M35: 1215.82 | N35: 1215.82 | O35: =SUM(C35:N35) | P35: 1318.02 | Q35: 1318.02 | R35: 1318.02 | S35: 1318.02 | T35: 1318.02 | U35: 1318.02 | V35: 1318.02 | W35: 1318.02 | X35: 1318.02 | Y35: 1318.02 | Z35: 1318.02 | AA35: 1318.02 | AB35: =SUM(P35:AA35) | AC35: 1226.25 | AD35: 1226.25 | AE35: 1226.25 | AF35: 1226.25 | AG35: 1226.25 | AH35: 1226.25 | AI35: 1226.25 | AJ35: 1226.25 | AK35: 1226.25 | AL35: 1226.25 | AM35: 1177.52 | AN35: 1177.52 | AO35: =SUM(AC35:AN35)
B36: HOA | C36: 397.48 | D36: 397.48 | E36: 397.48 | F36: 397.48 | G36: 397.48 | H36: 397.48 | I36: 397.48 | J36: 397.48 | K36: 397.48 | L36: 397.48 | M36: 397.48 | N36: 397.48 | O36: =SUM(C36:N36) | P36: 401.46 | Q36: 401.46 | R36: 401.46 | S36: 401.46 | T36: 401.46 | U36: 401.46 | V36: 401.46 | W36: 401.46 | X36: 401.46 | Y36: 401.46 | Z36: 401.46 | AA36: 401.46 | AB36: =SUM(P36:AA36) | AC36: 421.53 | AD36: 421.53 | AE36: 421.53 | AF36: 421.53 | AG36: 421.53 | AH36: 421.53 | AI36: 421.53 | AJ36: 421.53 | AK36: 421.53 | AL36: 421.53 | AM36: 421.53 | AN36: 421.53 | AO36: =SUM(AC36:AN36)
B37: ELECTRICAL WORK (GROUNDING, ESTIMATE, KITCHEN) | C37: 0 | D37: 0 | E37: 0 | F37: 0 | G37: 0 | H37: 0 | I37: 0 | J37: 0 | K37: 0 | L37: 350 | M37: 0 | N37: 0 | O37: =SUM(C37:N37) | P37: 0 | Q37: 0 | R37: 0 | S37: 0 | T37: 0 | U37: 0 | V37: 0 | W37: 0 | X37: 0 | Z37: 0 | AA37: 0 | AB37: =SUM(P37:AA37) | AC37: 0 | AD37: 0 | AE37: 0 | AF37: 0 | AG37: 0 | AH37: 0 | AI37: 0 | AJ37: 0 | AK37: 0 | AM37: 0 | AN37: 0 | AO37: =SUM(AC37:AN37)
B38: MOVE OUT FEE | C38: 0 | D38: 0 | E38: 0 | F38: 0 | G38: 0 | H38: 0 | I38: 0 | J38: 0 | K38: 0 | L38: 200 | M38: 0 | N38: 0 | O38: =SUM(C38:N38) | P38: 0 | Q38: 0 | R38: 0 | S38: 0 | T38: 0 | U38: 0 | V38: 0 | W38: 0 | X38: 0 | Y38: 200 | Z38: 0 | AA38: 0 | AB38: =SUM(P38:AA38) | AC38: 0 | AD38: 0 | AE38: 0 | AF38: 0 | AG38: 0 | AH38: 0 | AI38: 0 | AJ38: 0 | AK38: 0 | AL38: 300 | AM38: 0 | AN38: 0 | AO38: =SUM(AC38:AN38)
C39: 0 | D39: 0 | E39: 0 | F39: 0 | G39: 0 | H39: 0 | I39: 0 | J39: 0 | K39: 0 | L39: 0 | M39: 0 | N39: 0 | O39: =SUM(C39:N39) | P39: 0 | Q39: 0 | R39: 0 | S39: 0 | T39: 0 | U39: 0 | V39: 0 | W39: 0 | X39: 0 | Y39: 0 | Z39: 0 | AA39: 0 | AB39: =SUM(P39:AA39) | AC39: 0 | AD39: 0 | AE39: 0 | AF39: 0 | AG39: 0 | AH39: 0 | AI39: 0 | AJ39: 0 | AK39: 0 | AL39: 0 | AM39: 0 | AN39: 0 | AO39: =SUM(AC39:AN39)
C40: 0 | D40: 0 | E40: 0 | F40: 0 | G40: 0 | H40: 0 | I40: 0 | J40: 0 | K40: 0 | L40: 0 | M40: 0 | N40: 0 | O40: =SUM(C40:N40) | P40: 0 | Q40: 0 | R40: 0 | S40: 0 | T40: 0 | U40: 0 | V40: 0 | W40: 0 | X40: 0 | Y40: 0 | Z40: 0 | AA40: 0 | AB40: =SUM(P40:AA40) | AC40: 0 | AD40: 0 | AE40: 0 | AF40: 0 | AG40: 0 | AH40: 0 | AI40: 0 | AJ40: 0 | AK40: 0 | AL40: 0 | AM40: 0 | AN40: 0 | AO40: =SUM(AC40:AN40)
C41: 0 | D41: 0 | E41: 0 | F41: 0 | G41: 0 | H41: 0 | I41: 0 | J41: 0 | K41: 0 | L41: 0 | M41: 0 | N41: 0 | O41: =SUM(C41:N41) | P41: 0 | Q41: 0 | R41: 0 | S41: 0 | T41: 0 | U41: 0 | V41: 0 | W41: 0 | X41: 0 | Y41: 0 | Z41: 0 | AA41: 0 | AB41: =SUM(P41:AA41) | AC41: 0 | AD41: 0 | AE41: 0 | AF41: 0 | AG41: 0 | AH41: 0 | AI41: 0 | AJ41: 0 | AK41: 0 | AL41: 0 | AM41: 0 | AN41: 0 | AO41: =SUM(AC41:AN41)
...

Sheet EPGC LLC
A1: 2023
A2: INCOME | B2: JAN | C2: FEB | D2: MAR | E2: APR | F2: MAY | G2: JUN | H2: JUL | I2: AUG | J2: SEP | K2: OCT | L2: NOV | M2: DEC | N2: YEARLY
A3: Art Sales | F3: 8135.65 | G3: 11661.5 | H3: 50000 | J3: 400 | L3: 10700 | M3: 3040 | N3: =SUM(B3:M3)
A4: Consultant | N4: =SUM(B4:M4)
A5: Total | B5: =SUM(B3:B4) | C5: =SUM(C3:C4) | D5: =SUM(D3:D4) | E5: =SUM(E3:E4) | F5: =SUM(F3:F4) | G5: =SUM(G3:G4) | H5: =SUM(H3:H4) | I5: =SUM(I3:I4) | ... N5: =SUM(N3:N4)
A7: EXPENSES | B7: JAN | C7: FEB | D7: MAR | E7: APR | F7: MAY | G7: JUN | H7: JUL | I7: AUG | J7: SEP | K7: OCT | L7: NOV | M7: DEC | N7: YEARLY
A8: Supplies (office and operating) | N8: =SUM(B8:M8)
A9: Office Construction | J9: 13750 | N9: =SUM(B9:M9)
A10: Office Interior | I10: 426.52 | J10: 87.99 | K10: 87.78 | N10: =SUM(B10:M10)
A11: Office Furniture | I11: 461 | K11: 1799.5 | L11: 82.68 | N11: =SUM(B11:M11)
A12: Repairs and maintenance | N12: =SUM(B12:M12)
A13: Advertising | B13: 15 | C13: 15 | D13: 15 | E13: 15 | F13: 15 | G13: 15 | H13: 15 | I13: 15 | J13: 15 | K13: 15 | L13: 15 | M13: 15 | N13: =SUM(B13:M13)
A14: Travel, Meals, and Entertainment | C14: 1185.36 | E14: 1113.09 | H14: 50 | J14: 1351.31 | L14: 1283.75 | N14: =SUM(B14:M14)
A15: Accounting and legal | B15: 228 | C15: 20 | N15: =SUM(B15:M15)
A16: Cellphone and Internet | B16: 77.45 | C16: 77.45 | D16: 77.45 | E16: 77.45 | F16: 77.45 | G16: 77.45 | H16: 77.45 | I16: 77.45 | J16: 77.45 | K16: 77.45 | L16: 77.45 | M16: 77.45 | N16: =SUM(B16:M16)
A17: Software Fees | B17: 53 | C17: 53 | D17: 53 | E17: 53 | F17: 53 | G17: 53 | H17: 53 | I17: 53 | J17: 53 | K17: 53 | L17: 53 | M17: 53 | N17: =SUM(B17:M17)
A18: Tech | J18: 77.16 | K18: 384.99 | N18: =SUM(B18:M18)
A19: Art Library | B19: 5025.37 | N19: =SUM(B19:M19)
A20: Utilities | N20: =SUM(B20:M20)
A21: Insurance | N21: =SUM(B21:M21)
A22: TOTAL EXPENSES | B22: =SUM(B8:B21) | C22: =SUM(C8:C21) | D22: =SUM(D8:D21) | E22: =SUM(E8:E21) | F22: =SUM(F8:F21) | G22: =SUM(G8:G21) | H22: =SUM(H8:H21) | I22: =SUM(I8:I21) | ... N22: =SUM(N8:N21)
A24: YEAR TO DATE LESS EXPENSES | B24: =SUM(B5-B22) | C24: =SUM(C5-C22) | D24: =SUM(D5-D22) | E24: =SUM(E5-E22) | F24: =SUM(F5-F22) | G24: =SUM(G5-G22) | H24: =SUM(H5-H22) | I24: =SUM(I5-I22) | ... N24: =SUM(N5-N22)
A26: 2024
A27: INCOME | B27: JAN | C27: FEB | D27: MAR | E27: APR | F27: MAY | G27: JUN | H27: JUL | I27: AUG | J27: SEP | K27: OCT | L27: NOV | M27: DEC | N27: YEARLY
A28: Art Sales | N28: 26294.06
A29: Consultant | N29: =SUM(B29:M29)
A30: Total | B30: =SUM(B28:B29) | C30: =SUM(C28:C29) | D30: =SUM(D28:D29) | E30: =SUM(E28:E29) | F30: =SUM(F28:F29) | G30: =SUM(G28:G29) | H30: =SUM(H28:H29) | I30: =SUM(I28:I29) | ... N30: =SUM(N28:N29)
A32: EXPENSES | B32: JAN | C32: FEB | D32: MAR | E32: APR | F32: MAY | G32: JUN | H32: JUL | I32: AUG | J32: SEP | K32: OCT | L32: NOV | M32: DEC | N32: YEARLY
A33: Supplies (office and operating) | B33: 13.59 | C33: 5.94 | D33: 31.89 | N33: =SUM(B33:M33)
A34: Office Construction | N34: =SUM(B34:M34)
A35: Office Interior | N35: =SUM(B35:M35)
A36: Office Furniture | G36: 263.98 | H36: 165 | N36: =SUM(B36:M36)
A37: Repairs and maintenance | N37: =SUM(B37:M37)
A38: Advertising | D38: 60 | E38: 164.86 | F38: 34.91 | N38: =SUM(B38:M38)
A39: Travel, Meals, and Entertainment | C39: 1169.05 | E39: 1613.5 | J39: 923.42 | L39: 1059.45 | N39: =SUM(B39:M39)
A40: Accounting and legal | N40: =SUM(B40:M40)
A41: Cellphone and Internet | B41: 77.66 | C41: 77.45 | D41: 77.45 | E41: 77.43 | F41: 77.43 | G41: 162.86 | H41: 267.46 | I41: 88.54 | J41: 88.72 | K41: 93.61 | L41: 111.83 | M41: 106.67 | N41: =SUM(B41:M41)
A42: Software Fees | B42: 30 | C42: 30 | D42: 30 | E42: 30 | F42: 30 | G42: 30 | H42: 30 | I42: 30 | J42: 30 | K42: 50 | L42: 50 | M42: 50 | N42: =SUM(B42:M42)
A43: Tech | E43: 20 | F43: 192 | L43: 628.59 | N43: =SUM(B43:M43)
A44: Consultant Fees | J44: 316.5 | N44: =SUM(B44:M44)
...

Sheet Refrence Library
A1: Book | B1: From | C1: Purchase Price | D1: Purchase Date | E1: Method
A2: A Collection of Pre Columbian Auction Catalogues and Art Refrence Books | B2: N. Fagin | C2: 669.21 | D2: 44767 | E2: Check
A3: A Collection of Numismatic Journals | B3: John Meyes | C3: 200 | D3: 44839 | E3: Check
A4: A Collection of Joel Malter Catalogues | B4: M. Malter | C4: 301.46 | D4: 44634 | E4: Check
A5: A Collection of Antiquities Catalogues | B5: C. Murphy | C5: 700 | D5: 44519 | E5: Check
A6: The Beverley Collection of Gems at Alnwick Castle (The Philip Wilson Gems and Jewellery Series) | B6: Abebooks | C6: 30.05 | D6: 44905 | E6: Credit Card
A7: Masterpieces in Miniature The Philip Wilson Gems and Jewellery Series Engraved Gems from Prehistory to the Present | B7: Abebooks | C7: 50.37 | D7: 44905 | E7: Credit Card
A8: The First Treatise on Museums Samuel Quiccheberg's Inscriptiones, 1565 Texts Documents Paperback BIBLIOTHECA PAEDIATRICA REF KARGER | B8: Abebooks | C8: 30.64 | D8: 44812 | E8: Credit Card
A9: Greek Gems and Finger Rings: Early Bronze to Late Classical | B9: Abebooks | C9: 16.22 | D9: 44796 | E9: Credit Card
A10: The Maya Book of the Dead: The Ceramic Codex | B10: Abebooks | C10: 73.3 | D10: 44782 | E10: Credit Card
A11: 21 Masterpieces of Pre-Columbian Sculpture | B11: Abebooks | C11: 79.69 | D11: 44782 | E11: Credit Card
A12: TABLEAUX ANCIENS DES XVIe, XVIIe, XVIIIe ET XIXe SIECLES. OBJETS D'ARTS, SIEGES ET MEUBLES DES xviiE, XVIIIe ET XIXe SIECLES | B12: Abebooks | C12: 24.47 | D12: 44782 | E12: Credit Card
A13: Ladders to Heaven: Art Treasures from Lands of the Bible | B13: Abebooks | C13: 10.97 | D13: 37336 | E13: Credit Card
... A56: 100 Werke Antiker Kleinkunst Katalog 1 | B56: Abebooks | C56: 18.06 | D56: 44919 | E56: Credit Card
A57: Total | C57: =SUM(C2:C56)
A59: 2023
A60: A Catalogue of Engraved Gems in the British Museum: Department of Greek and Roman Antiquities | B60: Abebooks | C60: 5.37 | D60: 44563 | E60: Credit Card
A61: Cyclinder Seals | B61: Ebay | C61: 20 | E61: Credit Card
A62: A Collection of Auction and Dealer Catalogues | B62: Forge&Lynch | C62: 5000 | E62: Wire
A63: Total | C63: 5025.37
A65: 2024
A66: Lost Cities of the Mayas: | B66: Abebooks | C66: 65.56 | E66: Credit Card
A67: Renaissance Jewels and Jeweled Objects, from the Melvin Gutman Collection | B67: Abebooks | C67: 25.23 | E67: Credit Card
A68: Christie's Catalogue Northwick Park | B68: Ebay | C68: 28.55 | D68: 45654 | E68: Credit Card
A69: Harmer Rooke 1986 | B69: Ebay | C69: 11.69 | D69: 45546 | E69: Credit Card
A70: Grimani Palace Flyer | B70: Ebay | C70: 16.91 | D70: 45442 | E70: Credit Card
A71: CoC Book | B71: Amazon | C71: 49.5 | E71: Credit Card
A72: Total | C72: =SUM(C66:C71)
A74: 2025
A75: Jewelry Books | B75: Fred Schultz Library | C75: 1000 | D75: 45664 | E75: Wire

Sheet Art Sales and Purchases
A2: Sales 2022
A3: Object | B3: From | C3: Cost | D3: Purchase Date | E3: To | F3: Sale Price | G3: Sale Date | H3: Net Income | I3: ROI (%) | J3: Days in Inventory
A4: An Ashanti Wood Fertility Figure | B4: Live Auctioneers | C4: 450 | D4: 44344 | E4: Hindman | F4: 500 | G4: 44755 | H4: =SUM(F4-C4) | I4: =H4/C4 | J4: =G4-D4
A5: A Large Maya Hardstone Celt | B5: Live Auctioneers | C5: 906.37 | D5: 44535 | E5: Hindman | F5: 1000 | G5: 44755 | H5: =SUM(F5-C5) | I5: =H5/C5 | J5: =G5-D5
A6: A Mezcala Stone Figure | B6: Live Auctioneers | C6: 239 | D6: 44548 | E6: Hindman | F6: 400 | G6: 44755 | H6: =SUM(F6-C6) | I6: =H6/C6 | J6: =G6-D6
A7: A Veracruz Sonriente Figure | B7: Live Auctioneers | C7: 900 | D7: 44569 | E7: Hindman | F7: 1100 | G7: 44755 | H7: =SUM(F7-C7) | I7: =H7/C7 | J7: =G7-D7
A8: A Tairona Metal Tumbaga | B8: Live Auctioneers | C8: 172 | D8: 44569 | E8: Hindman | F8: 375 | G8: 44755 | H8: =SUM(F8-C8) | I8: =H8/C8 | J8: =G8-D8
A9: Four Thracian Gilt-Silver Double Eagle Plaques | B9: Hindman | C9: 400 | D9: 44343 | E9: Hindman | F9: 500 | G9: 44877 | H9: =SUM(F9-C9) | I9: =H9/C9 | J9: =G9-D9
A10: A Thracian Gilt-Silver Tondo of a Female Bust | B10: Hindman | C10: 375 | D10: 44343 | E10: Hindman | F10: 700 | G10: 44877 | H10: =SUM(F10-C10) | I10: =H10/C10 | J10: =G10-D10
A11: A Pair of Canosan Painted Pottery Oinochoai | B11: Hindman | C11: 6250 | D11: 44343 | E11: Hindman | F11: 15000 | G11: 44877 | H11: =SUM(F11-C11) | I11: =H11/C11 | J11: =G11-D11
A12: Thirteen Saharan Stone Bracelets and Discoidals | B12: Amyas Naegele | C12: 6100 | D12: 44692 | E12: Aquinas Hobor | F12: 8000 | G12: 44908 | H12: =SUM(F12-C12) | I12: =H12/C12 | J12: =G12-D12
A13: A Greek Style Bronze Corinthian Helmet | B13: EBay | C13: 5250.97 | D13: 44895 | E13: Marco Mercanti | F13: 9000 | G13: 44908 | H13: =SUM(F13-C13) | I13: =H13/C13 | J13: =G13-D13
A14: Total | C14: =SUM(C4:C13) | F14: =SUM(F4:F13) | H14: =SUM(H4:H13) | I14: =H14/C14 | J14: =AVERAGE(J4:J13)
A15: Sales 2023
A16: Object | B16: From | C16: Cost | D16: Purchase Date | E16: To | F16: Sale Price | G16: Sale Date | H16: Net Income
A17: Greek Bronze Cheek Pieces | B17: eBay | C17: 2870.43 | D17: 44918 | E17: Hindman | F17: 8500 | G17: 45071 | H17: =SUM(F17-C17) | I17: =H17/C17 | J17: =G17-D17
A18: Egyptian Neolithic Flint Tools (2) | B18: Arte Primitivo | C18: 392.14 | D18: 44908 | E18: Hindman | F18: 2500 | G18: 45071 | H18: =SUM(F18-C18) | I18: =H18/C18 | J18: =G18-D18
A19: Apulian Red Figure Fragment | B19: Aaron Berk | C19: 750 | D19: 44718 | E19: Hindman | F19: 600 | G19: 45071 | H19: =SUM(F19-C19) | I19: =H19/C19 | J19: =G19-D19
A20: A Roman-Style Rock Crystal Amphoriskos | B20: Live Auctioneers | C20: 1351.78 | D20: 44770 | E20: Hindman | F20: 1900 | G20: 45071 | H20: =SUM(F20-C20) | I20: =H20/C20 | J20: =G20-D20
A21: A Roman Mosaic | B21: ebay | C21: 3938 | D21: 45087 | E21: Aaron Berk | F21: 8500 | G21: 45099 | H21: =SUM(F21-C21) | I21: =H21/C21 | J21: =G21-D21
A22: Pre-Columbian Jade Earspools | B22: Live Auctioneers | C22: 233 | D22: 45086 | E22: Aaron Berk | F22: 500 | G22: 45099 | H22: =SUM(F22-C22) | I22: =H22/C22 | J22: =G22-D22
A23: Teo Alabaster Mask | B23: Live Auctioneers | C23: 701.5 | D23: 45086 | E23: Aaron Berk | F23: 2000 | G23: 45099 | H23: =SUM(F23-C23) | I23: =H23/C23 | J23: =G23-D23
A24: Mezcala Stone Temple | B24: Live Auctioneers | C24: 233 | D24: 45086 | E24: Aaron Berk | F24: 500 | G24: 45099 | H24: =SUM(F24-C24) | I24: =H24/C24 | J24: =G24-D24
A25: Mezcala Stone Figure | B25: Live Auctioneers | C25: 233 | D25: 45086 | E25: Aaron Berk | F25: 500 | G25: 45099 | H25: =SUM(F25-C25) | I25: =H25/C25 | J25: =G25-D25
A26: GREEK BRONZE HELMET OF PHRYGIAN TYPE | B26: ebay | C26: 2000 | D26: 44918 | E26: Aaron Berk | F26: 7000 | G26: 45099 | H26: =SUM(F26-C26) | I26: =H26/C26 | J26: =G26-D26
A27: Bactrian Style Stone Votive | B27: ebay | C27: 990 | D27: 44918 | E27: Aaron Berk | F27: 1000 | G27: 45099 | H27: =SUM(F27-C27) | I27: =H27/C27 | J27: =G27-D27
A28: A Roman Bronze Knife | B28: Ebay | C28: 110 | D28: 44988 | E28: Gift | F28: 100 | G28: 45097 | H28: =SUM(F28-C28) | I28: =H28/C28 | J28: =G28-D28
... A36: Native America Banner Stone (Anthro) | B36: Amyas Naegele | C36: 50 | D36: 44911 | E36: Harlan J. Berk | F36: 100 | G36: 45261 | H36: =SUM(F36-C36) | I36: =H36/C36 | J36: =G36-D36
A37: Total | C37: =SUM(C17:C36) | F37: =SUM(F17:F36) | H37: =SUM(H17:H36) | I37: =H37/C37 | J37: =AVERAGE(J17:J36)
A38: Sales 2024
A39: Object | B39: From | C39: Cost | D39: Purchase Date | E39: To | F39: Sale Price | G39: Sale Date | H39: Net Income
A40: A Valdivian Stone Votive Axe | B40: Arte Primitivo | C40: 470 | D40: 45196 | E40: Hindman | F40: 600 | G40: 45000 | H40: =SUM(F40-C40) | I40: =H40/C40
A41: A Roman Marble Leg | B41: Harlan J. Berk | C41: 2500 | D41: 45379 | E41: WhiteCube | F41: 2982 | G41: 45379 | H41: =SUM(F41-C41) | I41: =H41/C41
A42: Sword 10th Century Viking | B42: Zevantiques | C42: 1416.99 | D42: 45311 | E42: Harlan J. Berk | F42: 6500 | G42: 45448 | H42: =SUM(F42-C42) | I42: =H42/C42
A43: A Collection of Cylinder Seal | B43: Erdal Dere | C43: 33000 | D43: 45468 | E43: Harlan J. Berk | F43: 36000 | G43: 45468 | H43: =SUM(F43-C43)
A44: A Roman Glass Beaker | B44: Erdal Dere | C44: 25000 | D44: 45408 | E44: Erdal Dere | F44: 37500 | G44: 45656 | H44: =SUM(F44-C44) | I44: =H44/C44
A45: An Egyptian Limestone Head of a Pharaoh | B45: Live Auctioneers | C45: 1885.96 | D45: 45414 | E45: Harlan J. Berk | F45: 5500 | G45: 45621 | H45: =SUM(F45-C45) | I45: =H45/C45
A46: Indus Valley Vessels | B46: Ebay | C46: 214.99 | D46: 45345 | E46: Hindman | F46: 1700 | G46: 45435 | H46: =SUM(F46-C46) | I46: =H46/C46
A47: Total | C47: =SUM(C40:C46) | F47: =SUM(F40:F46) | H47: =SUM(H40:H46) | I47: =H47/C47 | J47: =AVERAGE(J26:J46)
A49: Sales 2025
...

Sheet GCM
A2: GCM Boards 2022
A3: Fees | B3: Q1 | C3: Q2 | D3: Q3 | E3: Q4
A4: GCM Board | B4: 3500 | C4: 3500 | D4: 3500 | E4: 7000
A5: Gates SPC | C5: 2500 | D5: 2500 | E5: 2500
A6: Total | B6: =SUM(B4:B5) | C6: =SUM(C4:C5) | D6: =SUM(D4:D5) | E6: =SUM(E4:E5)
A7: Grand Total | E7: =SUM(B6:E6)
A9: GCM Boards 2023
A10: Fees | B10: Q1 | C10: Q2 | D10: Q3 | E10: Q4
A11: GCM Board | B11: 3675 | C11: 3675 | D11: 3675 | E11: 3675
A12: Total | B12: =SUM(B11) | C12: =SUM(C11) | D12: =SUM(D11) | E12: =SUM(E11)
A13: Grand Total | E13: =SUM(B12:E12)
A15: GCM Boards 2024
A16: Fees | B16: Q1 | C16: Q2 | D16: Q3 | E16: Q4
A17: GCM Board | B17: 4050 | C17: 4050 | D17: 4050 | E17: 4050
A18: Total | B18: =SUM(B17) | C18: =SUM(C17) | D18: =SUM(D17) | E18: =SUM(E17)
A19: Grand Total | E19: =SUM(B18:E18)
A22: GCM Boards 2025
A23: Fees | B23: Q1 | C23: Q2 | D23: Q3 | E23: Q4
A24: GCM Board | B24: 4100 | C24: 9200 | D24: 4100 | E24: 4100
A25: Total | B25: =SUM(B24) | C25: =SUM(C24) | D25: =SUM(D24) | E25: =SUM(E24)
A26: Grand Total | E26: =SUM(B25:E25)
A28: BOM PAYMEN $21,500 = Form 1099-NEC (personal, Jacob). NOT EPGC Consultant. JAKE C / SEFOF reimbursements excluded. Not tax advice.

Sheet Hindman W2
A2: Contractual Employee 2023
A3: Income | B3: Q1 | C3: Q2 | D3: Q3 | E3: Q4
A4: Salary
A5: Bonus
A6: Total | B6: =SUM(B4) | C6: =SUM(C4) | D6: =SUM(D4) | E6: =SUM(E4)
A7: Total Revenues | E7: 115000
A9: Contractual Employee 2024
A10: Income | B10: Q1 | C10: Q2 | D10: Q3 | E10: Q4
A11: Salary
A12: Bonus
A13: Total | B13: =SUM(B11) | C13: =SUM(C11) | D13: =SUM(D11) | E13: =SUM(E11)
A14: Total Revenues | E14: 110000

Sheet Megan T4
A3: Contractual Employee 2022
A4: Income | B4: Q1 | C4: Q2 | D4: Q3 | E4: Q4
A5: Salary | B5: 23000 | C5: 23000 | D5: 23000 | E5: 23000
A6: Total | B6: =SUM(B5) | C6: =SUM(C5) | D6: =SUM(D5) | E6: =SUM(E5)
A7: Total Revenues | E7: =SUM(B6:E6)
A9: Contractual Employee 2023
A10: Income | B10: Q1 | C10: Q2 | D10: Q3 | E10: Q4
A11: Salary
A12: Total | B12: =SUM(B11) | C12: =SUM(C11) | D12: =SUM(D11) | E12: =SUM(E11)
A13: Total Revenues | E13: 100274
A15: Contractual Employee 2024
A16: Income | B16: Q1 | C16: Q2 | D16: Q3 | E16: Q4
A17: Salary
A18: Total | B18: =SUM(B17) | C18: =SUM(C17) | D18: =SUM(D17) | E18: =SUM(E17)
A19: Total Revenues

Sheet Investments
A1: Fidelity | B1: SEP IRA
A2: ML | B2: UTMA EMMA COLEY
A3: ML | B3: UTMA PHOEBE COLEY
A5: Coinbase (ACH from Mercury 8291) | B5: Investment transfers — not EPGC Art Sales, not advisory. Distinct from Coinbase 6108 card.
B6: JAN | C6: FEB | D6: MAR | E6: APR | F6: MAY | G6: JUN | H6: JUL | I6: AUG | J6: SEP | K6: OCT | L6: NOV | M6: DEC | N6: 2025 NET
A7: To Coinbase (funding) | B7: 0 | C7: 0 | D7: 0 | E7: 0 | F7: 0 | G7: 0 | H7: 0 | I7: 0 | J7: -9000 | K7: -10000 | L7: -35000 | M7: -5000 | N7: =SUM(B7:M7)
A8: From Coinbase (back to 8291) | B8: 0 | C8: 0 | D8: 0 | E8: 0 | F8: 0 | G8: 0 | H8: 0 | I8: 0 | J8: 0 | K8: 0 | L8: 0 | M8: 8000 | N8: =SUM(B8:M8)
A9: Net transfer | B9: 0 | C9: 0 | D9: 0 | E9: 0 | F9: 0 | G9: 0 | H9: 0 | I9: 0 | J9: -9000 | K9: -10000 | L9: -35000 | M9: 3000 | N9: =SUM(B9:M9)
A11: 2025: funded $59,000.00 / returned $8,000.00 / net $-51,000.00 off the EPGC operating account. Not income, not an expense. Not tax advice.

Sheet 524 Ferdinand Ave, Unit 1
B1: PROPERTY ADDRESS | C1: 524 Ferdinand Avenue, Unit 1 | P1: 524 Ferdinand Avenue, Unit 1
B2: INCOME | C2: JAN | D2: FEB | E2: MAR | F2: APR | G2: MAY | H2: JUN | I2: JUL | J2: AUG | K2: SEPT | L2: OCT | M2: NOV | N2: DEC | O2: 2023 YR TOTAL | P2: JAN | Q2: FEB | R2: MAR | S2: APR | T2: MAY | U2: JUN | V2: JUL | W2: AUG | X2: SEPT | Y2: OCT | Z2: NOV | AA2: DEC | AB2: 2025 YR TOTAL
B3: MULTI-PROPERTY INCOME OVERVIEW
B4: MULTI-PROPERTY INCOME OVERVIEW | C4: 0 | D4: 0 | E4: 0 | F4: 0 | G4: 0 | H4: 0 | I4: 0 | J4: 0 | K4: 0 | L4: 0 | M4: 0 | N4: 0 | O4: =SUM(C4:N4) | P4: 0 | Q4: 0 | R4: 0 | S4: 0 | T4: 0 | U4: 0 | V4: 0 | W4: 0 | X4: 0 | Y4: 0 | Z4: 0 | AA4: 0 | AB4: =SUM(P4:AA4)
B5: RENTAL INCOME | O5: =SUM(C5:N5) | AB5: =SUM(P5:AA5)
B6: GROSS RENTAL INCOME | C6: =SUM(C4:C5) | D6: =SUM(D4:D5) | E6: =SUM(E4:E5) | F6: =SUM(F4:F5) | G6: =SUM(G4:G5) | H6: =SUM(H4:H5) | I6: =SUM(I4:I5) | J6: =SUM(J4:J5) | ... N6: =SUM(N4:N5) | O6: =SUM(C6:N6) | P6: =SUM(P4:P5) | Q6: =SUM(Q4:Q5) | R6: =SUM(R4:R5) | S6: =SUM(S4:S5) | T6: =SUM(T4:T5) | U6: =SUM(U4:U5) | V6: =SUM(V4:V5) | W6: =SUM(W4:W5) | ... AA6: =SUM(AA4:AA5) | AB6: =SUM(P6:AA6)
B8: EXPENSES | C8: JAN | D8: FEB | E8: MAR | F8: APR | G8: MAY | H8: JUN | I8: JUL | J8: AUG | K8: SEPT | L8: OCT | M8: NOV | N8: DEC | O8: YR TOTAL | P8: JAN | Q8: FEB | R8: MAR | S8: APR | T8: MAY | U8: JUN | V8: JUL | W8: AUG | X8: SEPT | Y8: OCT | Z8: NOV | AA8: DEC | AB8: YR TOTAL
B10: MULTI-PROPERTY EXPENSES OVERVIEW | C10: 0 | D10: 0 | E10: 0 | F10: 0 | G10: 0 | H10: 0 | I10: 0 | J10: 0 | K10: 0 | L10: 0 | M10: 0 | N10: 0 | O10: =SUM(C10:N10) | P10: 0 | Q10: 0 | R10: 0 | S10: 0 | T10: 0 | U10: 0 | V10: 0 | W10: 0 | X10: 0 | Y10: 0 | Z10: 0 | AA10: 0 | AB10: =SUM(P10:AA10)
B11: MARKETING / ADVERTISING | C11: 0 | D11: 0 | E11: 0 | F11: 0 | G11: 0 | H11: 0 | I11: 0 | J11: 0 | K11: 0 | L11: 0 | M11: 0 | N11: 0 | O11: =SUM(C11:N11) | P11: 0 | Q11: 0 | R11: 0 | S11: 0 | T11: 0 | U11: 0 | V11: 0 | W11: 0 | X11: 0 | Y11: 0 | Z11: 0 | AA11: 0 | AB11: =SUM(P11:AA11)
B12: SERVICE FEES | C12: 0 | D12: 0 | E12: 0 | F12: 0 | G12: 0 | H12: 0 | I12: 0 | J12: 0 | K12: 0 | L12: 0 | M12: 0 | N12: 0 | O12: =SUM(C12:N12) | P12: 0 | Q12: 0 | R12: 0 | S12: 0 | T12: 0 | U12: 0 | V12: 0 | W12: 0 | X12: 0 | Y12: 0 | Z12: 0 | AA12: 0 | AB12: =SUM(P12:AA12)
B13: REMITTED TAX | C13: 0 | D13: 0 | E13: 0 | F13: 0 | G13: 0 | H13: 0 | I13: 0 | J13: 0 | K13: 0 | L13: 0 | M13: 0 | N13: 0 | O13: =SUM(C13:N13) | P13: 0 | Q13: 0 | R13: 0 | S13: 0 | T13: 0 | U13: 0 | V13: 0 | W13: 0 | X13: 0 | Y13: 0 | Z13: 0 | AA13: 0 | AB13: =SUM(P13:AA13)
B14: INSURANCE | N14: 1455.09 | O14: =SUM(C14:N14) | P14: 0 | Q14: 78.76 | R14: 78.75 | S14: 78.75 | T14: 78.75 | U14: 78.75 | V14: 78.75 | W14: 80.19 | X14: 0 | Y14: 0 | Z14: 0 | AA14: 0 | AB14: =SUM(P14:AA14)
B15: INTERIOR MAINTENANCE | C15: 0 | D15: 0 | E15: 0 | F15: 0 | G15: 0 | H15: 0 | I15: 0 | J15: 0 | K15: 0 | L15: 0 | M15: 0 | N15: 0 | O15: =SUM(C15:N15) | P15: 0 | Q15: 0 | R15: 0 | S15: 0 | T15: 0 | U15: 0 | V15: 0 | W15: 0 | X15: 0 | Y15: 0 | Z15: 0 | AA15: 0 | AB15: =SUM(P15:AA15)
B16: EXTERIOR REPAIRS | C16: 0 | D16: 0 | E16: 0 | F16: 0 | G16: 0 | H16: 0 | I16: 0 | J16: 851.32 | K16: 0 | L16: 0 | M16: 0 | N16: 0 | O16: =SUM(C16:N16) | P16: 0 | Q16: 66.56 | R16: 688.6 | S16: 39.57 | T16: 0 | U16: 0 | V16: 50.99 | W16: 0 | X16: 34.86 | Y16: 68.48 | Z16: 32.33 | AA16: 0 | AB16: =SUM(P16:AA16)
B17: GROUNDSKEEPING | C17: 0 | D17: 0 | E17: 0 | F17: 0 | G17: 0 | H17: 0 | I17: 0 | J17: 0 | K17: 0 | L17: 0 | M17: 0 | O17: =SUM(C17:N17) | P17: 0 | Q17: 0 | R17: 0 | S17: 0 | T17: 0 | U17: 0 | V17: 0 | W17: 0 | X17: 0 | Y17: 0 | Z17: 0 | AB17: =SUM(P17:AA17)
C18: 0 | D18: 0 | E18: 0 | F18: 0 | G18: 0 | H18: 0 | I18: 0 | J18: 0 | K18: 0 | L18: 0 | M18: 0 | N18: 0 | O18: =SUM(C18:N18) | P18: 0 | Q18: 0 | R18: 0 | S18: 0 | T18: 0 | U18: 0 | V18: 0 | W18: 0 | X18: 0 | Y18: 0 | Z18: 0 | AA18: 0 | AB18: =SUM(P18:AA18)
C19: 0 | D19: 0 | E19: 0 | F19: 0 | G19: 0 | H19: 0 | I19: 0 | J19: 0 | K19: 0 | L19: 0 | M19: 0 | N19: 0 | O19: =SUM(C19:N19) | P19: 0 | Q19: 0 | R19: 0 | S19: 0 | T19: 0 | U19: 0 | V19: 0 | W19: 0 | X19: 0 | Y19: 0 | Z19: 0 | AA19: 0 | AB19: =SUM(P19:AA19)
C20: 0 | D20: 0 | E20: 0 | F20: 0 | G20: 0 | H20: 0 | I20: 0 | J20: 0 | K20: 0 | L20: 0 | M20: 0 | N20: 0 | O20: =SUM(C20:N20) | P20: 0 | Q20: 0 | R20: 0 | S20: 0 | T20: 0 | U20: 0 | V20: 0 | W20: 0 | X20: 0 | Y20: 0 | Z20: 0 | AA20: 0 | AB20: =SUM(P20:AA20)
B21: VILLAGE WATER AND REFUSE | C21: 0 | D21: 0 | E21: 0 | F21: 0 | G21: 0 | H21: 0 | I21: 0 | J21: 118 | K21: 118 | L21: 118 | M21: 118 | N21: 118.29 | O21: =SUM(C21:N21) | P21: 0 | Q21: 100.55 | R21: 0 | S21: 90.67 | T21: 0 | U21: 112.83 | V21: 0 | W21: 137.63 | X21: 0 | Y21: 132.76 | Z21: 0 | AA21: 0 | AB21: =SUM(P21:AA21)
B22: GAS | C22: 0 | D22: 0 | E22: 0 | F22: 0 | G22: 0 | H22: 0 | I22: 0 | J22: 31.58 | K22: 66.56 | L22: 125.88 | M22: 86.68 | N22: 182.89 | O22: =SUM(C22:N22) | P22: 98.57 | Q22: 133.33 | R22: 115.82 | S22: 77.8 | T22: 79.95 | U22: 48.08 | V22: 0 | W22: 79.33 | X22: 36.25 | Y22: 38.22 | Z22: 0 | AA22: 139.35 | AB22: =SUM(P22:AA22)
B23: ELECTRIC | C23: 0 | D23: 0 | E23: 0 | F23: 0 | G23: 0 | H23: 0 | I23: 0 | J23: 98 | K23: 131.28 | L23: 71.5 | M23: 58.77 | N23: 84.62 | O23: =SUM(C23:N23) | P23: 132.94 | Q23: 216.44 | R23: 184.09 | S23: 60.95 | T23: 83.76 | U23: 69.69 | V23: 164.88 | W23: 203.43 | X23: 187.63 | Y23: 139.78 | Z23: 71.29 | AA23: 50.38 | AB23: =SUM(P23:AA23)
B24: INTERNET | C24: 45 | D24: 45 | E24: 45 | F24: 45 | G24: 45 | H24: 45 | I24: 45 | J24: 45 | K24: 45 | L24: 45 | M24: 45 | N24: 45 | O24: =SUM(C24:N24) | P24: 0 | Q24: 0 | R24: 0 | S24: 0 | T24: 0 | U24: 0 | V24: 0 | W24: 0 | X24: 0 | Y24: 0 | Z24: 0 | AA24: 0 | AB24: =SUM(P24:AA24)
B25: CORRESPONCES | C25: 0 | D25: 0 | E25: 0 | F25: 0 | G25: 0 | H25: 0 | I25: 0 | J25: 0 | K25: 0 | L25: 0 | M25: 0 | N25: 0 | O25: =SUM(C25:N25) | P25: 0 | Q25: 0 | R25: 0 | S25: 0 | T25: 0 | U25: 0 | V25: 0 | W25: 0 | X25: 0 | Y25: 0 | Z25: 0 | AA25: 0 | AB25: =SUM(P25:AA25)
B26: INTERIOR DESINGOR | C26: 0 | D26: 0 | E26: 0 | F26: 0 | G26: 0 | H26: 0 | I26: 0 | J26: 0 | K26: 0 | L26: 0 | M26: 0 | N26: 0 | O26: =SUM(C26:N26) | P26: 0 | Q26: 0 | R26: 0 | S26: 0 | T26: 0 | U26: 0 | V26: 0 | W26: 0 | X26: 0 | Y26: 0 | Z26: 0 | AA26: 0 | AB26: =SUM(P26:AA26)
B27: TRAVEL EXPENSES | C27: 0 | D27: 0 | E27: 0 | F27: 0 | G27: 0 | H27: 0 | I27: 0 | J27: 0 | K27: 0 | L27: 0 | M27: 0 | N27: 0 | O27: =SUM(C27:N27) | P27: 0 | Q27: 0 | R27: 0 | S27: 0 | T27: 0 | U27: 0 | V27: 0 | W27: 0 | X27: 0 | Y27: 0 | Z27: 0 | AA27: 0 | AB27: =SUM(P27:AA27)
B28: EQUIPMENT/APPLIANCE PURCHASES | C28: 0 | E28: 0 | F28: 0 | G28: 0 | H28: 0 | I28: 0 | J28: 3000 | K28: 0 | L28: 0 | M28: 0 | O28: =SUM(C28:N28) | P28: 0 | R28: 0 | S28: 0 | T28: 0 | U28: 0 | V28: 0 | W28: 0 | X28: 0 | Y28: 0 | Z28: 0 | AB28: =SUM(P28:AA28)
B29: EQUIPMENT/APPLIANCE RENTAL FEES | C29: 0 | D29: 0 | E29: 0 | F29: 0 | G29: 0 | H29: 0 | I29: 0 | J29: 0 | K29: 0 | L29: 0 | M29: 0 | N29: 0 | O29: =SUM(C29:N29) | P29: 0 | Q29: 0 | R29: 0 | S29: 0 | T29: 0 | U29: 0 | V29: 0 | W29: 0 | X29: 0 | Y29: 0 | Z29: 0 | AA29: 0 | AB29: =SUM(P29:AA29)
B30: LAND TAX | C30: 0 | D30: 0 | E30: 0 | F30: 0 | G30: 0 | H30: 0 | I30: 0 | J30: 0 | K30: 0 | L30: 0 | M30: 0 | N30: 0 | O30: =SUM(C30:N30) | P30: 0 | Q30: 0 | R30: 0 | S30: 0 | T30: 0 | U30: 0 | V30: 0 | W30: 0 | X30: 0 | Y30: 0 | Z30: 0 | AA30: 0 | AB30: =SUM(P30:AA30)
B31: BORROWING EXPENSES | C31: 0 | D31: 0 | E31: 0 | F31: 0 | G31: 0 | H31: 0 | I31: 0 | J31: 0 | K31: 0 | L31: 0 | M31: 0 | N31: 0 | O31: =SUM(C31:N31) | P31: 0 | Q31: 0 | R31: 0 | S31: 0 | T31: 0 | U31: 0 | V31: 0 | W31: 0 | X31: 0 | Y31: 0 | Z31: 0 | AA31: 0 | AB31: =SUM(P31:AA31)
B32: LOANS INTEREST | C32: 0 | D32: 0 | E32: 0 | F32: 0 | G32: 0 | H32: 0 | I32: 0 | J32: 0 | K32: 0 | L32: 0 | M32: 0 | N32: 0 | O32: =SUM(C32:N32) | P32: 0 | Q32: 0 | R32: 0 | S32: 0 | T32: 0 | U32: 0 | V32: 0 | W32: 0 | X32: 0 | Y32: 0 | Z32: 0 | AA32: 0 | AB32: =SUM(P32:AA32)
B33: TRAVEL EXPENSES | C33: 0 | D33: 0 | E33: 0 | F33: 0 | G33: 0 | H33: 0 | I33: 0 | J33: 0 | K33: 0 | L33: 0 | M33: 0 | N33: 0 | O33: =SUM(C33:N33) | P33: 0 | Q33: 0 | R33: 0 | S33: 0 | T33: 0 | U33: 0 | V33: 0 | W33: 0 | X33: 0 | Y33: 0 | Z33: 0 | AA33: 0 | AB33: =SUM(P33:AA33)
B34: MORTGAGE | L34: 3920.64 | M34: 3920.64 | N34: 3920.64 | O34: =SUM(C34:N34) | P34: 4287.51 | Q34: 4287.51 | R34: 4287.51 | S34: 4287.51 | T34: 4287.51 | U34: 4287.51 | V34: 4287.51 | W34: 5089.77 | X34: 5089.77 | Y34: 4438.69 | Z34: 4438.69 | AA34: 4377.54 | AB34: =SUM(P34:AA34)
B35: HOA | O35: =SUM(C35:N35) | AB35: =SUM(P35:AA35)
B36: TERMITE INSPECTION | C36: 0 | D36: 0 | E36: 0 | G36: 0 | H36: 0 | I36: 0 | J36: 145 | K36: 0 | L36: 0 | N36: 0 | O36: =SUM(C36:N36) | P36: 0 | Q36: 0 | R36: 0 | T36: 0 | U36: 0 | V36: 0 | W36: 0 | X36: 0 | Y36: 0 | AA36: 0 | AB36: =SUM(P36:AA36)
B37: OTHER | C37: 0 | D37: 0 | E37: 0 | F37: 0 | G37: 0 | H37: 0 | I37: 0 | J37: 0 | M37: 0 | N37: 0 | O37: =SUM(C37:N37) | P37: 0 | Q37: 0 | R37: 0 | S37: 0 | T37: 0 | U37: 0 | V37: 0 | W37: 0 | Z37: 0 | AA37: 0 | AB37: =SUM(P37:AA37)
B38: OTHER | C38: 0 | D38: 0 | E38: 0 | F38: 0 | G38: 0 | H38: 0 | I38: 0 | J38: 0 | K38: 0 | O38: =SUM(C38:N38) | P38: 0 | Q38: 0 | R38: 0 | S38: 0 | T38: 0 | U38: 0 | V38: 0 | W38: 0 | X38: 0 | AB38: =SUM(P38:AA38)
C39: 0 | D39: 0 | E39: 0 | F39: 0 | G39: 0 | H39: 0 | I39: 0 | J39: 0 | K39: 0 | L39: 0 | M39: 0 | N39: 0 | O39: =SUM(C39:N39) | P39: 0 | Q39: 0 | R39: 0 | S39: 0 | T39: 0 | U39: 0 | V39: 0 | W39: 0 | X39: 0 | Y39: 0 | Z39: 0 | AA39: 0 | AB39: =SUM(P39:AA39)
C40: 0 | D40: 0 | E40: 0 | F40: 0 | G40: 0 | H40: 0 | I40: 0 | J40: 0 | K40: 0 | L40: 0 | M40: 0 | N40: 0 | O40: =SUM(C40:N40) | P40: 0 | Q40: 0 | R40: 0 | S40: 0 | T40: 0 | U40: 0 | V40: 0 | W40: 0 | X40: 0 | Y40: 0 | Z40: 0 | AA40: 0 | AB40: =SUM(P40:AA40)
B41: TOTAL EXPENSES | C41: =SUM(C10:C40) | D41: =SUM(D10:D40) | E41: =SUM(E10:E40) | F41: =SUM(F10:F40) | G41: =SUM(G10:G40) | H41: =SUM(H10:H40) | I41: =SUM(I10:I40) | J41: =SUM(J10:J40) | ... N41: =SUM(N10:N40) | O41: =SUM(C41:N41) | P41: =SUM(P10:P40) | Q41: =SUM(Q10:Q40) | R41: =SUM(R10:R40) | S41: =SUM(S10:S40) | T41: =SUM(T10:T40) | U41: =SUM(U10:U40) | V41: =SUM(V10:V40) | W41: =SUM(W10:W40) | ... AA41: =SUM(AA10:AA40) | AB41: =SUM(P41:AA41)
B43: YEAR-TO-DATE INCOME LESS EXPENSES | C43: =C6-C41 | D43: =D6-D41 | E43: =E6-E41 | F43: =F6-F41 | G43: =G6-G41 | H43: =H6-H41 | I43: =I6-I41 | J43: =J6-J41 | ... AB43: =AB6-AB41
...

Sheet 2025 Data sources
A1: HOW THIS FILE IS MADE
A2: This is last year's Personal Income.xlsx with a 2025 year block filled in. 2023 and 2024 are unchanged. Do not rebuild from CSVs.
A3: Last year file (model) | B3: Drive Personal Income.xlsx | C3: 1qdewbEnTuc-DXdbqBmwHrKMetGm3I7Zo | D3: 132,313 bytes | E3: Unchanged 2023|2024
A4: This file | B4: Personal Income 2025.xlsx | C4: copy of that workbook + 2025 columns | E4: Same 11 tab names and order
A6: Tab | B6: Line | C6: 2025 amount | D6: Source | E6: Status
A7: Income | B7: Hindman actual I4 | C7: 70,618.00 | D7: Monarch paycheck cash (not W-2 Box 1) | E7: YELLOW — Box 1 still ASK
A8: Income | B8: 216 Oak Park I5 | C8: 19,500.00 | D8: Joint 0203 Delach + Ava + Joan cash | E8: LOCKED
A9: Income | B9: 524 #2 STR I6 | C9: 17,086.94 | D9: Airbnb/VRBO platform net | E9: LOCKED
A10: Income | B10: GCM Boards I7 | C10: 21,500.00 | D10: Form 1099-NEC BOM PAYMEN (personal, not EPGC) | E10: LOCKED
A11: Income | B11: Art Sales net I8 | C11: 23,055.06 | D11: MATCHED Mercury deals with Cost only (Berk lots + seals + mosaics). Sale 6428 and Aquinas books wait on Cost. | E11: LOCKED
A12: 216 Oak Park | B12: RENTAL INCOME | C12: 19,500.00 | D12: Same as Income I5. Vacant Oct + half Nov. | E12: LOCKED
